Workbook

Sheet SessionDB
A1: ID | B1: Day | C1: Start | D1: End | E1: Title | F1: Lead | G1: Room | H1: Type | I1: Track | J1: Capacity | K1: Expected Participants | R1: Tracks (auto)
A2: 1 | B2: 1 | C2: 09:00 | D2: 10:00 | E2: Opening Keynote | F2: Dr. Sarah Chen | G2: Main Hall | H2: Keynote | I2: all | J2: 200 | K2: 140 | R2: =sort(unique(filter(I2:I200,LOWER(I2:I200)<>"all")))
A3: 2 | B3: 1 | C3: 10:30 | D3: 12:00 | E3: Leading Through Change | F3: Mark Torres | G3: Room A1 | H3: Leadership | I3: Leadership | J3: 40 | K3: 28
A4: 3 | B4: 1 | C4: 10:30 | D4: 12:00 | E4: API Design Patterns | F4: Priya Sharma | G4: Room B1 | H4: Technical | I4: Technical | J4: 45 | K4: 31
A5: 4 | B5: 1 | C5: 10:30 | D5: 12:00 | E5: Empathy Mapping 101 | F5: Lena Müller | G5: Room C1 | H5: Design Thinking | I5: Design Thinking | J5: 35 | K5: 24
A6: 5 | B6: 1 | C6: 10:30 | D6: 12:00 | E6: Lean Process Improvement | F6: James Wright | G6: Room D1 | H6: Operations | I6: Operations | J6: 30 | K6: 21
A7: 6 | B7: 1 | C7: 12:00 | D7: 13:00 | E7: Lunch & Networking | G7: Atrium | H7: Break | I7: all | J7: 200 | K7: 200
A8: 7 | B8: 1 | C8: 13:00 | D8: 14:30 | E8: Stakeholder Alignment | F8: Aisha Johnson | G8: Room A1 | H8: Leadership | I8: Leadership | J8: 40 | K8: 28
A9: 8 | B9: 1 | C9: 13:00 | D9: 14:30 | E9: Cloud Infrastructure | F9: David Kim | G9: Room B1 | H9: Technical | I9: Technical | J9: 50 | K9: 35
A10: 9 | B10: 1 | C10: 13:00 | D10: 14:30 | E10: Prototyping Sprint | F10: Carlos Ruiz | G10: Room C1 | H10: Design Thinking | I10: Design Thinking | J10: 35 | K10: 24
A11: 10 | B11: 1 | C11: 13:00 | D11: 14:30 | E11: Risk Assessment | F11: Nina Petrov | G11: Room D1 | H11: Operations | I11: Operations | J11: 30 | K11: 21
A12: 11 | B12: 1 | C12: 14:30 | D12: 15:00 | E12: Afternoon Break | G12: Atrium | H12: Break | I12: all | J12: 200 | K12: 200
A13: 12 | B13: 1 | C13: 15:00 | D13: 16:30 | E13: Feedback Culture | F13: Tom Bradley | G13: Room A1 | H13: Leadership | I13: Leadership | J13: 38 | K13: 26
A14: 13 | B14: 1 | C14: 15:00 | D14: 16:30 | E14: Data Pipeline Design | F14: Wei Zhang | G14: Room B1 | H14: Technical | I14: Technical | J14: 42 | K14: 29
A15: 14 | B15: 1 | C15: 15:00 | D15: 16:30 | E15: Service Blueprinting | F15: Lena Müller | G15: Room C1 | H15: Design Thinking | I15: Design Thinking | J15: 32 | K15: 22
A16: 15 | B16: 1 | C16: 15:00 | D16: 16:30 | E16: Agile Ceremonies | F16: Rachel Green | G16: Room D1 | H16: Operations | I16: Operations | J16: 28 | K16: 19
A17: 16 | B17: 2 | C17: 09:00 | D17: 10:30 | E17: Emotional Intelligence | F17: Aisha Johnson | G17: Room A1 | H17: Leadership | I17: Leadership | J17: 40 | K17: 28
A18: 17 | B18: 2 | C18: 09:00 | D18: 10:30 | E18: Security Fundamentals | F18: Alex Novak | G18: Room B1 | H18: Technical | I18: Technical | J18: 48 | K18: 33
A19: 18 | B19: 2 | C19: 09:00 | D19: 10:30 | E19: Design Systems | F19: Yuki Tanaka | G19: Room C1 | H19: Design Thinking | I19: Design Thinking | J19: 35 | K19: 24
A20: 19 | B20: 2 | C20: 09:00 | D20: 10:30 | E20: Capacity Planning | F20: James Wright | G20: Room D1 | H20: Operations | I20: Operations | J20: 30 | K20: 21
A21: 20 | B21: 2 | C21: 10:30 | D21: 11:00 | E21: Morning Break | G21: Atrium | H21: Break | I21: all | J21: 200 | K21: 200
A22: 21 | B22: 2 | C22: 11:00 | D22: 12:00 | E22: Panel: Future of Work | F22: Multiple Speakers | G22: Main Hall | H22: Keynote | I22: all | J22: 180 | K22: 125
A23: 22 | B23: 2 | C23: 12:00 | D23: 13:00 | E23: Lunch & Networking | G23: Atrium | H23: Break | I23: all | J23: 200 | K23: 200
A24: 23 | B24: 2 | C24: 13:00 | D24: 14:30 | E24: Conflict Resolution | F24: Mark Torres | G24: Room A1 | H24: Leadership | I24: Leadership | J24: 40 | K24: 28
A25: 24 | B25: 2 | C25: 13:00 | D25: 14:30 | E25: DevOps Practices | F25: Priya Sharma | G25: Room B1 | H25: Technical | I25: Technical | J25: 50 | K25: 35
A26: 25 | B26: 2 | C26: 13:00 | D26: 14:30 | E26: Accessibility Workshop | F26: Carlos Ruiz | G26: Room C1 | H26: Design Thinking | I26: Design Thinking | J26: 36 | K26: 25
A27: 26 | B27: 2 | C27: 13:00 | D27: 14:30 | E27: Vendor Management | F27: Nina Petrov | G27: Room D1 | H27: Operations | I27: Operations | J27: 28 | K27: 19
A28: 27 | B28: 2 | C28: 14:30 | D28: 15:00 | E28: Afternoon Break | G28: Atrium | H28: Break | I28: all | J28: 200 | K28: 200
A29: 28 | B29: 2 | C29: 15:00 | D29: 16:30 | E29: Strategic Planning | F29: Tom Bradley | G29: Room A1 | H29: Leadership | I29: Leadership | J29: 42 | K29: 29
A30: 29 | B30: 2 | C30: 15:00 | D30: 16:30 | E30: Performance Testing | F30: David Kim | G30: Room B1 | H30: Technical | I30: Technical | J30: 44 | K30: 30
A31: 30 | B31: 2 | C31: 15:00 | D31: 16:30 | E31: User Research Methods | F31: Yuki Tanaka | G31: Room C1 | H31: Design Thinking | I31: Design Thinking | J31: 34 | K31: 23
A32: 31 | B32: 2 | C32: 15:00 | D32: 16:30 | E32: Budget Forecasting | F32: Rachel Green | G32: Room D1 | H32: Operations | I32: Operations | J32: 26 | K32: 18
A33: 32 | B33: 3 | C33: 09:00 | D33: 10:00 | E33: Midweek Keynote | F33: Dr. Sarah Chen | G33: Main Hall | H33: Keynote | I33: all | J33: 190 | K33: 133
A34: 33 | B34: 3 | C34: 10:00 | D34: 10:30 | E34: Morning Break | G34: Atrium | H34: Break | I34: all | J34: 200 | K34: 200
A35: 34 | B35: 3 | C35: 10:30 | D35: 12:00 | E35: Cross-Team Collaboration | F35: Aisha Johnson | G35: Room A1 | H35: Leadership | I35: Leadership | J35: 40 | K35: 28
A36: 35 | B36: 3 | C36: 10:30 | D36: 12:00 | E36: AI/ML Integration | F36: Wei Zhang | G36: Room B1 | H36: Technical | I36: Technical | J36: 52 | K36: 36
A37: 36 | B37: 3 | C37: 10:30 | D37: 12:00 | E37: Workshop Facilitation | F37: Lena Müller | G37: Room C1 | H37: Design Thinking | I37: Design Thinking | J37: 34 | K37: 23
A38: 37 | B38: 3 | C38: 10:30 | D38: 12:00 | E38: Incident Response | F38: Alex Novak | G38: Room D1 | H38: Operations | I38: Operations | J38: 30 | K38: 21
A39: 38 | B39: 3 | C39: 12:00 | D39: 13:00 | E39: Lunch & Networking | G39: Atrium | H39: Break | I39: all | J39: 200 | K39: 200
A40: 39 | B40: 3 | C40: 13:00 | D40: 16:30 | E40: Cross-Track Hackathon | F40: All Facilitators | G40: All Rooms | H40: Keynote | I40: all | J40: 200 | K40: 140
...

Sheet ParticipantsDB
A1: ID | B1: Username | C1: Email | D1: Department | E1: Job Title | F1: Primary Track | G1: Non-Local | H1: Hotel | I1: Day 1 | J1: Day 2 | K1: Day 3 | L1: Day 4 | M1: Day 5 | N1: Emergency Contact | O1: Emergency Phone | P1: Notes
A2: P001 | B2: alice.martinez | C2: alice.martinez@acme.com | D2: Product | E2: Product Manager | F2: Leadership | G2: Local | I2: Yes | J2: Yes | K2: Yes | L2: Yes | M2: Yes | N2: John Martinez | O2: +1-555-0101
A3: P002 | B3: ben.okafor | C3: ben.okafor@techstart.io | D3: Engineering | E3: Senior Developer | F3: Technical | G3: Non-Local | H3: Hilton Downtown | I3: Yes | J3: Yes | K3: Yes | L3: Yes | M3: No | N3: Mary Okafor | O3: +1-555-0102
A4: P003 | B4: clara.johansson | C4: clara.j@nordicdesign.se | D4: Design | E4: UX Lead | F4: Design Thinking | G4: Non-Local | H4: Marriott Convention | I4: Yes | J4: Yes | K4: Yes | L4: Yes | M4: Yes | N4: Erik Johansson | O4: +46-70-555-0103
A5: P004 | B5: daniel.park | C5: d.park@globalops.com | D5: Operations | E5: Ops Director | F5: Operations | G5: Local | I5: Yes | J5: No | K5: Yes | L5: Yes | M5: Yes | N5: Soo-Min Park | O5: +1-555-0104
A6: P005 | B6: elena.rossi | C6: e.rossi@finserv.it | D6: Strategy | E6: Team Lead | F6: Leadership | G6: Non-Local | H6: Hyatt Regency | I6: Yes | J6: Yes | K6: No | L6: Yes | M6: Yes | N6: Marco Rossi | O6: +39-555-0105
A7: P006 | B7: fatima.alhassan | C7: f.alhassan@govtech.ae | D7: Engineering | E7: Systems Architect | F7: Technical | G7: Non-Local | H7: Hilton Downtown | I7: Yes | J7: Yes | K7: Yes | L7: Yes | M7: Yes | N7: Ahmed Al-Hassan | O7: +971-55-0106
A8: P007 | B8: george.chen | C8: g.chen@startuplab.cn | D8: Design | E8: Design Director | F8: Design Thinking | G8: Non-Local | H8: Marriott Convention | I8: Yes | J8: Yes | K8: Yes | L8: No | M8: Yes | N8: Wei Chen | O8: +86-138-0107
A9: P008 | B9: hannah.weber | C9: h.weber@logicorp.de | D9: Operations | E9: Process Engineer | F9: Operations | G9: Non-Local | H9: Holiday Inn Express | I9: Yes | J9: Yes | K9: Yes | L9: Yes | M9: Yes | N9: Thomas Weber | O9: +49-170-0108
A10: P009 | B10: ibrahim.diallo | C10: i.diallo@afrotech.sn | D10: Engineering | E10: Eng. Manager | F10: Technical | G10: Non-Local | H10: Hyatt Regency | I10: No | J10: Yes | K10: Yes | L10: Yes | M10: Yes | N10: Aminata Diallo | O10: +221-77-0109
A11: P010 | B11: julia.fernandez | C11: j.fernandez@consulta.mx | D11: Strategy | E11: Strategy Consultant | F11: Leadership | G11: Non-Local | H11: Hilton Downtown | I11: Yes | J11: Yes | K11: Yes | L11: Yes | M11: Yes | N11: Roberto Fernandez | O11: +52-55-0110
A12: P011 | B12: kevin.obrien | C12: k.obrien@dublinsoft.ie | D12: Engineering | E12: DevOps Lead | F12: Technical | G12: Non-Local | H12: Marriott Convention | I12: Yes | J12: Yes | K12: Yes | L12: Yes | M12: No | N12: Siobhan O'Brien | O12: +353-86-0111
A13: P012 | B13: lina.nakamura | C13: l.nakamura@tokyoux.jp | D13: Design | E13: Service Designer | F13: Design Thinking | G13: Non-Local | H13: Holiday Inn Express | I13: Yes | J13: No | K13: Yes | L13: Yes | M13: Yes | N13: Yuki Nakamura | O13: +81-90-0112
A14: P013 | B14: marcus.brown | C14: m.brown@opscenter.us | D14: Logistics | E14: Logistics Mgr | F14: Operations | G14: Local | I14: Yes | J14: Yes | K14: Yes | L14: Yes | M14: Yes | N14: Sarah Brown | O14: +1-555-0113
A15: P014 | B15: nadia.kovalenko | C15: n.kovalenko@dataflow.ua | D15: Data | E15: Data Engineer | F15: Technical | G15: Non-Local | H15: Hyatt Regency | I15: Yes | J15: Yes | K15: Yes | L15: Yes | M15: Yes | N15: Oleksandr K. | O15: +380-67-0114
A16: P015 | B16: oscar.lindgren | C16: o.lindgren@greentech.se | D16: Sustainability | E16: Sustainability Lead | F16: Operations | G16: Non-Local | H16: Marriott Convention | I16: Yes | J16: Yes | K16: No | L16: Yes | M16: Yes | N16: Anna Lindgren | O16: +46-73-0115
A17: P016 | B17: priya.menon | C17: p.menon@cloudnine.in | D17: Engineering | E17: VP Engineering | F17: Technical | G17: Non-Local | H17: Hilton Downtown | I17: Yes | J17: Yes | K17: Yes | L17: Yes | M17: Yes | N17: Raj Menon | O17: +91-98-0116
A18: P017 | B18: quentin.dubois | C18: q.dubois@parislab.fr | D18: Innovation | E18: Innovation Lead | F18: Design Thinking | G18: Non-Local | H18: Holiday Inn Express | I18: Yes | J18: Yes | K18: Yes | L18: Yes | M18: No | N18: Marie Dubois | O18: +33-6-0117
A19: P018 | B19: rachel.kim | C19: r.kim@seoultech.kr | D19: Operations | E19: Project Manager | F19: Operations | G19: Non-Local | H19: Hilton Downtown | I19: Yes | J19: Yes | K19: Yes | L19: Yes | M19: Yes | N19: Jun Kim | O19: +82-10-0118
A20: P019 | B20: sam.adeyemi | C20: s.adeyemi@lagosops.ng | D20: Executive | E20: COO | F20: Leadership | G20: Non-Local | H20: Hyatt Regency | I20: Yes | J20: Yes | K20: Yes | L20: No | M20: Yes | N20: Grace Adeyemi | O20: +234-80-0119
A21: P020 | B21: tara.singh | C21: t.singh@quantumleap.ca | D21: Engineering | E21: CTO | F21: Technical | G21: Local | I21: Yes | J21: Yes | K21: Yes | L21: Yes | M21: Yes | N21: Arjun Singh | O21: +1-604-0120

Sheet Participants Statistics
A1: PARTICIPANTS STATISTICS | G1: HotelList | H1: DeptList
G2: =sort(unique(filter(ParticipantsDB!H2:H200,(ParticipantsDB!H2:H200<>"")*(LEN(ParticipantsDB!H2:H200)>0)))) | H2: =sort(unique(filter(ParticipantsDB!D2:D200,(ParticipantsDB!D2:D200<>"")*(LEN(ParticipantsDB!D2:D200)>0))))
A3: TOTAL OVERVIEW | D3: HOTEL BREAKDOWN
A4: Total Participants | B4: =COUNTA(ParticipantsDB!A2:A200) | D4: =IFERROR(INDEX($G$2:$G$50,1),"") | E4: =IF(D4="","",COUNTIF(ParticipantsDB!H2:H200,D4))
A5: Local Participants | B5: =COUNTIF(ParticipantsDB!G2:G200,"Local") | D5: =IFERROR(INDEX($G$2:$G$50,2),"") | E5: =IF(D5="","",COUNTIF(ParticipantsDB!H2:H200,D5))
A6: Non-Local Participants | B6: =COUNTIF(ParticipantsDB!G2:G200,"Non-Local") | D6: =IFERROR(INDEX($G$2:$G$50,3),"") | E6: =IF(D6="","",COUNTIF(ParticipantsDB!H2:H200,D6))
A7: Non-Local % | B7: =IFERROR(COUNTIF(ParticipantsDB!G2:G200,"Non-Local")/COUNTA(ParticipantsDB!A2:A200),0) | D7: =IFERROR(INDEX($G$2:$G$50,4),"") | E7: =IF(D7="","",COUNTIF(ParticipantsDB!H2:H200,D7))
D8: =IFERROR(INDEX($G$2:$G$50,5),"") | E8: =IF(D8="","",COUNTIF(ParticipantsDB!H2:H200,D8))
A9: DAILY ATTENDANCE | D9: =IFERROR(INDEX($G$2:$G$50,6),"") | E9: =IF(D9="","",COUNTIF(ParticipantsDB!H2:H200,D9))
A10: Day 1 — Mon Mar 9 | B10: =COUNTIF(ParticipantsDB!I2:I200,"Yes") | D10: =IFERROR(INDEX($G$2:$G$50,7),"") | E10: =IF(D10="","",COUNTIF(ParticipantsDB!H2:H200,D10))
A11: Day 2 — Tue Mar 10 | B11: =COUNTIF(ParticipantsDB!J2:J200,"Yes") | D11: =IFERROR(INDEX($G$2:$G$50,8),"") | E11: =IF(D11="","",COUNTIF(ParticipantsDB!H2:H200,D11))
A12: Day 3 — Wed Mar 11 | B12: =COUNTIF(ParticipantsDB!K2:K200,"Yes") | D12: =IFERROR(INDEX($G$2:$G$50,9),"") | E12: =IF(D12="","",COUNTIF(ParticipantsDB!H2:H200,D12))
A13: Day 4 — Thu Mar 12 | B13: =COUNTIF(ParticipantsDB!L2:L200,"Yes") | D13: =IFERROR(INDEX($G$2:$G$50,10),"") | E13: =IF(D13="","",COUNTIF(ParticipantsDB!H2:H200,D13))
A14: Day 5 — Fri Mar 13 | B14: =COUNTIF(ParticipantsDB!M2:M200,"Yes") | D14: No Hotel Assigned | E14: =COUNTIFS(ParticipantsDB!G2:G200,"Non-Local",ParticipantsDB!H2:H200,"")
A15: Highest Day | B15: =MAX(B10:B14) | D15: Total Non-Local (verify) | E15: =COUNTIF(ParticipantsDB!G2:G200,"Non-Local")
A16: Lowest Day | B16: =MIN(B10:B14)
A17: Avg Daily Attendance | B17: =IFERROR(AVERAGE(B10:B14),0) | D17: TRACK × LOCALITY
D18: =IF(IFERROR(INDEX(SessionDB!$R$2:$R$50,1),"")="","",IFERROR(INDEX(SessionDB!$R$2:$R$50,1),"")&" — Local") | E18: =IF(D18="","",COUNTIFS(ParticipantsDB!F2:F200,IFERROR(INDEX(SessionDB!$R$2:$R$50,1),""),ParticipantsDB!G2:G200,"Local"))
A19: BREAKDOWN BY TRACK | D19: =IF(IFERROR(INDEX(SessionDB!$R$2:$R$50,1),"")="","",IFERROR(INDEX(SessionDB!$R$2:$R$50,1),"")&" — Non-Local") | E19: =IF(D19="","",COUNTIFS(ParticipantsDB!F2:F200,IFERROR(INDEX(SessionDB!$R$2:$R$50,1),""),ParticipantsDB!G2:G200,"Non-Local"))
A20: =IFERROR(INDEX(SessionDB!$R$2:$R$50,1),"") | B20: =IF(A20="","",COUNTIF(ParticipantsDB!F2:F200,A20)) | D20: =IF(IFERROR(INDEX(SessionDB!$R$2:$R$50,2),"")="","",IFERROR(INDEX(SessionDB!$R$2:$R$50,2),"")&" — Local") | E20: =IF(D20="","",COUNTIFS(ParticipantsDB!F2:F200,IFERROR(INDEX(SessionDB!$R$2:$R$50,2),""),ParticipantsDB!G2:G200,"Local"))
A21: =IFERROR(INDEX(SessionDB!$R$2:$R$50,2),"") | B21: =IF(A21="","",COUNTIF(ParticipantsDB!F2:F200,A21)) | D21: =IF(IFERROR(INDEX(SessionDB!$R$2:$R$50,2),"")="","",IFERROR(INDEX(SessionDB!$R$2:$R$50,2),"")&" — Non-Local") | E21: =IF(D21="","",COUNTIFS(ParticipantsDB!F2:F200,IFERROR(INDEX(SessionDB!$R$2:$R$50,2),""),ParticipantsDB!G2:G200,"Non-Local"))
A22: =IFERROR(INDEX(SessionDB!$R$2:$R$50,3),"") | B22: =IF(A22="","",COUNTIF(ParticipantsDB!F2:F200,A22)) | D22: =IF(IFERROR(INDEX(SessionDB!$R$2:$R$50,3),"")="","",IFERROR(INDEX(SessionDB!$R$2:$R$50,3),"")&" — Local") | E22: =IF(D22="","",COUNTIFS(ParticipantsDB!F2:F200,IFERROR(INDEX(SessionDB!$R$2:$R$50,3),""),ParticipantsDB!G2:G200,"Local"))
A23: =IFERROR(INDEX(SessionDB!$R$2:$R$50,4),"") | B23: =IF(A23="","",COUNTIF(ParticipantsDB!F2:F200,A23)) | D23: =IF(IFERROR(INDEX(SessionDB!$R$2:$R$50,3),"")="","",IFERROR(INDEX(SessionDB!$R$2:$R$50,3),"")&" — Non-Local") | E23: =IF(D23="","",COUNTIFS(ParticipantsDB!F2:F200,IFERROR(INDEX(SessionDB!$R$2:$R$50,3),""),ParticipantsDB!G2:G200,"Non-Local"))
A24: =IFERROR(INDEX(SessionDB!$R$2:$R$50,5),"") | B24: =IF(A24="","",COUNTIF(ParticipantsDB!F2:F200,A24)) | D24: =IF(IFERROR(INDEX(SessionDB!$R$2:$R$50,4),"")="","",IFERROR(INDEX(SessionDB!$R$2:$R$50,4),"")&" — Local") | E24: =IF(D24="","",COUNTIFS(ParticipantsDB!F2:F200,IFERROR(INDEX(SessionDB!$R$2:$R$50,4),""),ParticipantsDB!G2:G200,"Local"))
A25: =IFERROR(INDEX(SessionDB!$R$2:$R$50,6),"") | B25: =IF(A25="","",COUNTIF(ParticipantsDB!F2:F200,A25)) | D25: =IF(IFERROR(INDEX(SessionDB!$R$2:$R$50,4),"")="","",IFERROR(INDEX(SessionDB!$R$2:$R$50,4),"")&" — Non-Local") | E25: =IF(D25="","",COUNTIFS(ParticipantsDB!F2:F200,IFERROR(INDEX(SessionDB!$R$2:$R$50,4),""),ParticipantsDB!G2:G200,"Non-Local"))
A26: =IFERROR(INDEX(SessionDB!$R$2:$R$50,7),"") | B26: =IF(A26="","",COUNTIF(ParticipantsDB!F2:F200,A26)) | D26: =IF(IFERROR(INDEX(SessionDB!$R$2:$R$50,5),"")="","",IFERROR(INDEX(SessionDB!$R$2:$R$50,5),"")&" — Local") | E26: =IF(D26="","",COUNTIFS(ParticipantsDB!F2:F200,IFERROR(INDEX(SessionDB!$R$2:$R$50,5),""),ParticipantsDB!G2:G200,"Local"))
A27: =IFERROR(INDEX(SessionDB!$R$2:$R$50,8),"") | B27: =IF(A27="","",COUNTIF(ParticipantsDB!F2:F200,A27)) | D27: =IF(IFERROR(INDEX(SessionDB!$R$2:$R$50,5),"")="","",IFERROR(INDEX(SessionDB!$R$2:$R$50,5),"")&" — Non-Local") | E27: =IF(D27="","",COUNTIFS(ParticipantsDB!F2:F200,IFERROR(INDEX(SessionDB!$R$2:$R$50,5),""),ParticipantsDB!G2:G200,"Non-Local"))
A28: =IFERROR(INDEX(SessionDB!$R$2:$R$50,9),"") | B28: =IF(A28="","",COUNTIF(ParticipantsDB!F2:F200,A28)) | D28: =IF(IFERROR(INDEX(SessionDB!$R$2:$R$50,6),"")="","",IFERROR(INDEX(SessionDB!$R$2:$R$50,6),"")&" — Local") | E28: =IF(D28="","",COUNTIFS(ParticipantsDB!F2:F200,IFERROR(INDEX(SessionDB!$R$2:$R$50,6),""),ParticipantsDB!G2:G200,"Local"))
A29: =IFERROR(INDEX(SessionDB!$R$2:$R$50,10),"") | B29: =IF(A29="","",COUNTIF(ParticipantsDB!F2:F200,A29)) | D29: =IF(IFERROR(INDEX(SessionDB!$R$2:$R$50,6),"")="","",IFERROR(INDEX(SessionDB!$R$2:$R$50,6),"")&" — Non-Local") | E29: =IF(D29="","",COUNTIFS(ParticipantsDB!F2:F200,IFERROR(INDEX(SessionDB!$R$2:$R$50,6),""),ParticipantsDB!G2:G200,"Non-Local"))
A30: Total (verify) | B30: =COUNTA(ParticipantsDB!A2:A200) | D30: =IF(IFERROR(INDEX(SessionDB!$R$2:$R$50,7),"")="","",IFERROR(INDEX(SessionDB!$R$2:$R$50,7),"")&" — Local") | E30: =IF(D30="","",COUNTIFS(ParticipantsDB!F2:F200,IFERROR(INDEX(SessionDB!$R$2:$R$50,7),""),ParticipantsDB!G2:G200,"Local"))
D31: =IF(IFERROR(INDEX(SessionDB!$R$2:$R$50,7),"")="","",IFERROR(INDEX(SessionDB!$R$2:$R$50,7),"")&" — Non-Local") | E31: =IF(D31="","",COUNTIFS(ParticipantsDB!F2:F200,IFERROR(INDEX(SessionDB!$R$2:$R$50,7),""),ParticipantsDB!G2:G200,"Non-Local"))
D32: =IF(IFERROR(INDEX(SessionDB!$R$2:$R$50,8),"")="","",IFERROR(INDEX(SessionDB!$R$2:$R$50,8),"")&" — Local") | E32: =IF(D32="","",COUNTIFS(ParticipantsDB!F2:F200,IFERROR(INDEX(SessionDB!$R$2:$R$50,8),""),ParticipantsDB!G2:G200,"Local"))
D33: =IF(IFERROR(INDEX(SessionDB!$R$2:$R$50,8),"")="","",IFERROR(INDEX(SessionDB!$R$2:$R$50,8),"")&" — Non-Local") | E33: =IF(D33="","",COUNTIFS(ParticipantsDB!F2:F200,IFERROR(INDEX(SessionDB!$R$2:$R$50,8),""),ParticipantsDB!G2:G200,"Non-Local"))
D34: =IF(IFERROR(INDEX(SessionDB!$R$2:$R$50,9),"")="","",IFERROR(INDEX(SessionDB!$R$2:$R$50,9),"")&" — Local") | E34: =IF(D34="","",COUNTIFS(ParticipantsDB!F2:F200,IFERROR(INDEX(SessionDB!$R$2:$R$50,9),""),ParticipantsDB!G2:G200,"Local"))
D35: =IF(IFERROR(INDEX(SessionDB!$R$2:$R$50,9),"")="","",IFERROR(INDEX(SessionDB!$R$2:$R$50,9),"")&" — Non-Local") | E35: =IF(D35="","",COUNTIFS(ParticipantsDB!F2:F200,IFERROR(INDEX(SessionDB!$R$2:$R$50,9),""),ParticipantsDB!G2:G200,"Non-Local"))
D36: =IF(IFERROR(INDEX(SessionDB!$R$2:$R$50,10),"")="","",IFERROR(INDEX(SessionDB!$R$2:$R$50,10),"")&" — Local") | E36: =IF(D36="","",COUNTIFS(ParticipantsDB!F2:F200,IFERROR(INDEX(SessionDB!$R$2:$R$50,10),""),ParticipantsDB!G2:G200,"Local"))
D37: =IF(IFERROR(INDEX(SessionDB!$R$2:$R$50,10),"")="","",IFERROR(INDEX(SessionDB!$R$2:$R$50,10),"")&" — Non-Local") | E37: =IF(D37="","",COUNTIFS(ParticipantsDB!F2:F200,IFERROR(INDEX(SessionDB!$R$2:$R$50,10),""),ParticipantsDB!G2:G200,"Non-Local"))
D39: DEPARTMENT BREAKDOWN
D40: =IFERROR(INDEX($H$2:$H$50,1),"") | E40: =IF(D40="","",COUNTIF(ParticipantsDB!D2:D200,D40))
D41: =IFERROR(INDEX($H$2:$H$50,2),"") | E41: =IF(D41="","",COUNTIF(ParticipantsDB!D2:D200,D41))
...

Sheet Room Management
A1: ROOM MANAGEMENT — Macro Populated from SessionDB
A2: Day | B2: Time | C2: Main Hall (200 pax) | D2: Room A1 (50 pax) | E2: Room B1 (55 pax) | F2: Room C1 (45 pax) | G2: Room D1 (40 pax) | H2: Atrium (250 pax) | I2: Room E1 (35 pax) | J2: Room E2 (30 pax) | K2: Room F1 (25 pax) | L2: Boardroom G (15 pax) | M2: Terrace (60 pax)
C3: Primary | D3: Primary | E3: Primary | F3: Primary | G3: Primary | H3: Primary | I3: Backup | J3: Backup | K3: Backup | L3: Backup | M3: Backup
A4: D1 | B4: 08:00
A5: D1 | B5: 08:30
A6: D1 | B6: 09:00
A7: D1 | B7: 09:30
A8: D1 | B8: 10:00
A9: D1 | B9: 10:30
A10: D1 | B10: 11:00
A11: D1 | B11: 11:30
A12: D1 | B12: 12:00
A13: D1 | B13: 12:30
A14: D1 | B14: 13:00
A15: D1 | B15: 13:30
... A103: D5 | B103: 17:30
A105: Run macro: Alt+F8 → RefreshRoomGrid → Run. Blue cells = session booked. Blank = available. To add a room: insert column, type header in row 2 and role in row 3, then re-run macro.

Sheet Day 1
A1: DAY 1: Mon Mar 9
A2: REFRESHED: 08 Mar 2026 13:00 | 4 tracks + Overall | Workshop 2026
A3: TIME | B3: OVERALL | C3: LEADERSHIP | D3: TECHNICAL | E3: DESIGN THINKING | F3: OPERATIONS
A4: 08:00 | I4: =IFERROR(INDEX(SessionDB!$H$2:$H$64,MATCH(1,(SessionDB!$B$2:$B$64=1)*(SessionDB!$C$2:$C$64=$A4)*((SessionDB!$I$2:$I$64=$E$3)+(SessionDB!$I$2:$I$64="all")),0)),IFERROR(INDEX(SessionDB!$H$2:$H$64,MATCH(1,(SessionDB!$B$2:$B$64=1)*(SessionDB!$C$2:$C$64<$A4)*(SessionDB!$D$2:$D$64>$A4)*((SessionDB!$I$2:$I$64=$E$3)+(SessionDB!$I$2:$I$64="all")),0)),""))
A5: 08:30 | I5: =IFERROR(INDEX(SessionDB!$H$2:$H$64,MATCH(1,(SessionDB!$B$2:$B$64=1)*(SessionDB!$C$2:$C$64=$A5)*((SessionDB!$I$2:$I$64=$E$3)+(SessionDB!$I$2:$I$64="all")),0)),IFERROR(INDEX(SessionDB!$H$2:$H$64,MATCH(1,(SessionDB!$B$2:$B$64=1)*(SessionDB!$C$2:$C$64<$A5)*(SessionDB!$D$2:$D$64>$A5)*((SessionDB!$I$2:$I$64=$E$3)+(SessionDB!$I$2:$I$64="all")),0)),""))
A6: 09:00 | B6: Opening Keynote Lead: Dr. Sarah Chen • Main Hall | I6: =IFERROR(INDEX(SessionDB!$H$2:$H$64,MATCH(1,(SessionDB!$B$2:$B$64=1)*(SessionDB!$C$2:$C$64=$A6)*((SessionDB!$I$2:$I$64=$E$3)+(SessionDB!$I$2:$I$64="all")),0)),IFERROR(INDEX(SessionDB!$H$2:$H$64,MATCH(1,(SessionDB!$B$2:$B$64=1)*(SessionDB!$C$2:$C$64<$A6)*(SessionDB!$D$2:$D$64>$A6)*((SessionDB!$I$2:$I$64=$E$3)+(SessionDB!$I$2:$I$64="all")),0)),""))
A7: 09:30 | I7: =IFERROR(INDEX(SessionDB!$H$2:$H$64,MATCH(1,(SessionDB!$B$2:$B$64=1)*(SessionDB!$C$2:$C$64=$A7)*((SessionDB!$I$2:$I$64=$E$3)+(SessionDB!$I$2:$I$64="all")),0)),IFERROR(INDEX(SessionDB!$H$2:$H$64,MATCH(1,(SessionDB!$B$2:$B$64=1)*(SessionDB!$C$2:$C$64<$A7)*(SessionDB!$D$2:$D$64>$A7)*((SessionDB!$I$2:$I$64=$E$3)+(SessionDB!$I$2:$I$64="all")),0)),""))
A8: 10:00 | I8: =IFERROR(INDEX(SessionDB!$H$2:$H$64,MATCH(1,(SessionDB!$B$2:$B$64=1)*(SessionDB!$C$2:$C$64=$A8)*((SessionDB!$I$2:$I$64=$E$3)+(SessionDB!$I$2:$I$64="all")),0)),IFERROR(INDEX(SessionDB!$H$2:$H$64,MATCH(1,(SessionDB!$B$2:$B$64=1)*(SessionDB!$C$2:$C$64<$A8)*(SessionDB!$D$2:$D$64>$A8)*((SessionDB!$I$2:$I$64=$E$3)+(SessionDB!$I$2:$I$64="all")),0)),""))
A9: 10:30 | C9: Leading Through Change Lead: Mark Torres • Room A1 | D9: API Design Patterns Lead: Priya Sharma • Room B1 | E9: Empathy Mapping 101 Lead: Lena Müller • Room C1 | F9: Lean Process Improvement Lead: James Wright • Room D1 | I9: =IFERROR(INDEX(SessionDB!$H$2:$H$64,MATCH(1,(SessionDB!$B$2:$B$64=1)*(SessionDB!$C$2:$C$64=$A9)*((SessionDB!$I$2:$I$64=$E$3)+(SessionDB!$I$2:$I$64="all")),0)),IFERROR(INDEX(SessionDB!$H$2:$H$64,MATCH(1,(SessionDB!$B$2:$B$64=1)*(SessionDB!$C$2:$C$64<$A9)*(SessionDB!$D$2:$D$64>$A9)*((SessionDB!$I$2:$I$64=$E$3)+(SessionDB!$I$2:$I$64="all")),0)),""))
A10: 11:00 | I10: =IFERROR(INDEX(SessionDB!$H$2:$H$64,MATCH(1,(SessionDB!$B$2:$B$64=1)*(SessionDB!$C$2:$C$64=$A10)*((SessionDB!$I$2:$I$64=$E$3)+(SessionDB!$I$2:$I$64="all")),0)),IFERROR(INDEX(SessionDB!$H$2:$H$64,MATCH(1,(SessionDB!$B$2:$B$64=1)*(SessionDB!$C$2:$C$64<$A10)*(SessionDB!$D$2:$D$64>$A10)*((SessionDB!$I$2:$I$64=$E$3)+(SessionDB!$I$2:$I$64="all")),0)),""))
A11: 11:30 | I11: =IFERROR(INDEX(SessionDB!$H$2:$H$64,MATCH(1,(SessionDB!$B$2:$B$64=1)*(SessionDB!$C$2:$C$64=$A11)*((SessionDB!$I$2:$I$64=$E$3)+(SessionDB!$I$2:$I$64="all")),0)),IFERROR(INDEX(SessionDB!$H$2:$H$64,MATCH(1,(SessionDB!$B$2:$B$64=1)*(SessionDB!$C$2:$C$64<$A11)*(SessionDB!$D$2:$D$64>$A11)*((SessionDB!$I$2:$I$64=$E$3)+(SessionDB!$I$2:$I$64="all")),0)),""))
A12: 12:00 | B12: Lunch & Networking | I12: =IFERROR(INDEX(SessionDB!$H$2:$H$64,MATCH(1,(SessionDB!$B$2:$B$64=1)*(SessionDB!$C$2:$C$64=$A12)*((SessionDB!$I$2:$I$64=$E$3)+(SessionDB!$I$2:$I$64="all")),0)),IFERROR(INDEX(SessionDB!$H$2:$H$64,MATCH(1,(SessionDB!$B$2:$B$64=1)*(SessionDB!$C$2:$C$64<$A12)*(SessionDB!$D$2:$D$64>$A12)*((SessionDB!$I$2:$I$64=$E$3)+(SessionDB!$I$2:$I$64="all")),0)),""))
A13: 12:30 | I13: =IFERROR(INDEX(SessionDB!$H$2:$H$64,MATCH(1,(SessionDB!$B$2:$B$64=1)*(SessionDB!$C$2:$C$64=$A13)*((SessionDB!$I$2:$I$64=$E$3)+(SessionDB!$I$2:$I$64="all")),0)),IFERROR(INDEX(SessionDB!$H$2:$H$64,MATCH(1,(SessionDB!$B$2:$B$64=1)*(SessionDB!$C$2:$C$64<$A13)*(SessionDB!$D$2:$D$64>$A13)*((SessionDB!$I$2:$I$64=$E$3)+(SessionDB!$I$2:$I$64="all")),0)),""))
A14: 13:00 | C14: Stakeholder Alignment Lead: Aisha Johnson • Room A1 | D14: Cloud Infrastructure Lead: David Kim • Room B1 | E14: Prototyping Sprint Lead: Carlos Ruiz • Room C1 | F14: Risk Assessment Lead: Nina Petrov • Room D1 | I14: =IFERROR(INDEX(SessionDB!$H$2:$H$64,MATCH(1,(SessionDB!$B$2:$B$64=1)*(SessionDB!$C$2:$C$64=$A14)*((SessionDB!$I$2:$I$64=$E$3)+(SessionDB!$I$2:$I$64="all")),0)),IFERROR(INDEX(SessionDB!$H$2:$H$64,MATCH(1,(SessionDB!$B$2:$B$64=1)*(SessionDB!$C$2:$C$64<$A14)*(SessionDB!$D$2:$D$64>$A14)*((SessionDB!$I$2:$I$64=$E$3)+(SessionDB!$I$2:$I$64="all")),0)),""))
A15: 13:30 | I15: =IFERROR(INDEX(SessionDB!$H$2:$H$64,MATCH(1,(SessionDB!$B$2:$B$64=1)*(SessionDB!$C$2:$C$64=$A15)*((SessionDB!$I$2:$I$64=$E$3)+(SessionDB!$I$2:$I$64="all")),0)),IFERROR(INDEX(SessionDB!$H$2:$H$64,MATCH(1,(SessionDB!$B$2:$B$64=1)*(SessionDB!$C$2:$C$64<$A15)*(SessionDB!$D$2:$D$64>$A15)*((SessionDB!$I$2:$I$64=$E$3)+(SessionDB!$I$2:$I$64="all")),0)),""))
A16: 14:00 | I16: =IFERROR(INDEX(SessionDB!$H$2:$H$64,MATCH(1,(SessionDB!$B$2:$B$64=1)*(SessionDB!$C$2:$C$64=$A16)*((SessionDB!$I$2:$I$64=$E$3)+(SessionDB!$I$2:$I$64="all")),0)),IFERROR(INDEX(SessionDB!$H$2:$H$64,MATCH(1,(SessionDB!$B$2:$B$64=1)*(SessionDB!$C$2:$C$64<$A16)*(SessionDB!$D$2:$D$64>$A16)*((SessionDB!$I$2:$I$64=$E$3)+(SessionDB!$I$2:$I$64="all")),0)),""))
A17: 14:30 | B17: Afternoon Break | I17: =IFERROR(INDEX(SessionDB!$H$2:$H$64,MATCH(1,(SessionDB!$B$2:$B$64=1)*(SessionDB!$C$2:$C$64=$A17)*((SessionDB!$I$2:$I$64=$E$3)+(SessionDB!$I$2:$I$64="all")),0)),IFERROR(INDEX(SessionDB!$H$2:$H$64,MATCH(1,(SessionDB!$B$2:$B$64=1)*(SessionDB!$C$2:$C$64<$A17)*(SessionDB!$D$2:$D$64>$A17)*((SessionDB!$I$2:$I$64=$E$3)+(SessionDB!$I$2:$I$64="all")),0)),""))
A18: 15:00 | C18: Feedback Culture Lead: Tom Bradley • Room A1 | D18: Data Pipeline Design Lead: Wei Zhang • Room B1 | E18: Service Blueprinting Lead: Lena Müller • Room C1 | F18: Agile Ceremonies Lead: Rachel Green • Room D1 | I18: =IFERROR(INDEX(SessionDB!$H$2:$H$64,MATCH(1,(SessionDB!$B$2:$B$64=1)*(SessionDB!$C$2:$C$64=$A18)*((SessionDB!$I$2:$I$64=$E$3)+(SessionDB!$I$2:$I$64="all")),0)),IFERROR(INDEX(SessionDB!$H$2:$H$64,MATCH(1,(SessionDB!$B$2:$B$64=1)*(SessionDB!$C$2:$C$64<$A18)*(SessionDB!$D$2:$D$64>$A18)*((SessionDB!$I$2:$I$64=$E$3)+(SessionDB!$I$2:$I$64="all")),0)),""))
A19: 15:30 | I19: =IFERROR(INDEX(SessionDB!$H$2:$H$64,MATCH(1,(SessionDB!$B$2:$B$64=1)*(SessionDB!$C$2:$C$64=$A19)*((SessionDB!$I$2:$I$64=$E$3)+(SessionDB!$I$2:$I$64="all")),0)),IFERROR(INDEX(SessionDB!$H$2:$H$64,MATCH(1,(SessionDB!$B$2:$B$64=1)*(SessionDB!$C$2:$C$64<$A19)*(SessionDB!$D$2:$D$64>$A19)*((SessionDB!$I$2:$I$64=$E$3)+(SessionDB!$I$2:$I$64="all")),0)),""))
A20: 16:00 | I20: =IFERROR(INDEX(SessionDB!$H$2:$H$64,MATCH(1,(SessionDB!$B$2:$B$64=1)*(SessionDB!$C$2:$C$64=$A20)*((SessionDB!$I$2:$I$64=$E$3)+(SessionDB!$I$2:$I$64="all")),0)),IFERROR(INDEX(SessionDB!$H$2:$H$64,MATCH(1,(SessionDB!$B$2:$B$64=1)*(SessionDB!$C$2:$C$64<$A20)*(SessionDB!$D$2:$D$64>$A20)*((SessionDB!$I$2:$I$64=$E$3)+(SessionDB!$I$2:$I$64="all")),0)),""))
A21: 16:30 | I21: =IFERROR(INDEX(SessionDB!$H$2:$H$64,MATCH(1,(SessionDB!$B$2:$B$64=1)*(SessionDB!$C$2:$C$64=$A21)*((SessionDB!$I$2:$I$64=$E$3)+(SessionDB!$I$2:$I$64="all")),0)),IFERROR(INDEX(SessionDB!$H$2:$H$64,MATCH(1,(SessionDB!$B$2:$B$64=1)*(SessionDB!$C$2:$C$64<$A21)*(SessionDB!$D$2:$D$64>$A21)*((SessionDB!$I$2:$I$64=$E$3)+(SessionDB!$I$2:$I$64="all")),0)),""))
A22: 17:00 | I22: =IFERROR(INDEX(SessionDB!$H$2:$H$64,MATCH(1,(SessionDB!$B$2:$B$64=1)*(SessionDB!$C$2:$C$64=$A22)*((SessionDB!$I$2:$I$64=$E$3)+(SessionDB!$I$2:$I$64="all")),0)),IFERROR(INDEX(SessionDB!$H$2:$H$64,MATCH(1,(SessionDB!$B$2:$B$64=1)*(SessionDB!$C$2:$C$64<$A22)*(SessionDB!$D$2:$D$64>$A22)*((SessionDB!$I$2:$I$64=$E$3)+(SessionDB!$I$2:$I$64="all")),0)),""))
A23: 17:30 | I23: =IFERROR(INDEX(SessionDB!$H$2:$H$64,MATCH(1,(SessionDB!$B$2:$B$64=1)*(SessionDB!$C$2:$C$64=$A23)*((SessionDB!$I$2:$I$64=$E$3)+(SessionDB!$I$2:$I$64="all")),0)),IFERROR(INDEX(SessionDB!$H$2:$H$64,MATCH(1,(SessionDB!$B$2:$B$64=1)*(SessionDB!$C$2:$C$64<$A23)*(SessionDB!$D$2:$D$64>$A23)*((SessionDB!$I$2:$I$64=$E$3)+(SessionDB!$I$2:$I$64="all")),0)),""))
A25: Tracks: Overall, Leadership, Technical, Design Thinking, Operations | Generated: 08 Mar 2026 13:00

Sheet Day 2
A1: DAY 2: Tue Mar 10
A2: REFRESHED: 08 Mar 2026 13:00 | 4 tracks + Overall | Workshop 2026
A3: TIME | B3: OVERALL | C3: LEADERSHIP | D3: TECHNICAL | E3: DESIGN THINKING | F3: OPERATIONS
A4: 08:00 | I4: =IFERROR(INDEX(SessionDB!$H$2:$H$64,MATCH(1,(SessionDB!$B$2:$B$64=2)*(SessionDB!$C$2:$C$64=$A4)*((SessionDB!$I$2:$I$64=$E$3)+(SessionDB!$I$2:$I$64="all")),0)),IFERROR(INDEX(SessionDB!$H$2:$H$64,MATCH(1,(SessionDB!$B$2:$B$64=2)*(SessionDB!$C$2:$C$64<$A4)*(SessionDB!$D$2:$D$64>$A4)*((SessionDB!$I$2:$I$64=$E$3)+(SessionDB!$I$2:$I$64="all")),0)),""))
A5: 08:30 | I5: =IFERROR(INDEX(SessionDB!$H$2:$H$64,MATCH(1,(SessionDB!$B$2:$B$64=2)*(SessionDB!$C$2:$C$64=$A5)*((SessionDB!$I$2:$I$64=$E$3)+(SessionDB!$I$2:$I$64="all")),0)),IFERROR(INDEX(SessionDB!$H$2:$H$64,MATCH(1,(SessionDB!$B$2:$B$64=2)*(SessionDB!$C$2:$C$64<$A5)*(SessionDB!$D$2:$D$64>$A5)*((SessionDB!$I$2:$I$64=$E$3)+(SessionDB!$I$2:$I$64="all")),0)),""))
A6: 09:00 | C6: Emotional Intelligence Lead: Aisha Johnson • Room A1 | D6: Security Fundamentals Lead: Alex Novak • Room B1 | E6: Design Systems Lead: Yuki Tanaka • Room C1 | F6: Capacity Planning Lead: James Wright • Room D1 | I6: =IFERROR(INDEX(SessionDB!$H$2:$H$64,MATCH(1,(SessionDB!$B$2:$B$64=2)*(SessionDB!$C$2:$C$64=$A6)*((SessionDB!$I$2:$I$64=$E$3)+(SessionDB!$I$2:$I$64="all")),0)),IFERROR(INDEX(SessionDB!$H$2:$H$64,MATCH(1,(SessionDB!$B$2:$B$64=2)*(SessionDB!$C$2:$C$64<$A6)*(SessionDB!$D$2:$D$64>$A6)*((SessionDB!$I$2:$I$64=$E$3)+(SessionDB!$I$2:$I$64="all")),0)),""))
A7: 09:30 | I7: =IFERROR(INDEX(SessionDB!$H$2:$H$64,MATCH(1,(SessionDB!$B$2:$B$64=2)*(SessionDB!$C$2:$C$64=$A7)*((SessionDB!$I$2:$I$64=$E$3)+(SessionDB!$I$2:$I$64="all")),0)),IFERROR(INDEX(SessionDB!$H$2:$H$64,MATCH(1,(SessionDB!$B$2:$B$64=2)*(SessionDB!$C$2:$C$64<$A7)*(SessionDB!$D$2:$D$64>$A7)*((SessionDB!$I$2:$I$64=$E$3)+(SessionDB!$I$2:$I$64="all")),0)),""))
A8: 10:00 | I8: =IFERROR(INDEX(SessionDB!$H$2:$H$64,MATCH(1,(SessionDB!$B$2:$B$64=2)*(SessionDB!$C$2:$C$64=$A8)*((SessionDB!$I$2:$I$64=$E$3)+(SessionDB!$I$2:$I$64="all")),0)),IFERROR(INDEX(SessionDB!$H$2:$H$64,MATCH(1,(SessionDB!$B$2:$B$64=2)*(SessionDB!$C$2:$C$64<$A8)*(SessionDB!$D$2:$D$64>$A8)*((SessionDB!$I$2:$I$64=$E$3)+(SessionDB!$I$2:$I$64="all")),0)),""))
A9: 10:30 | B9: Morning Break | I9: =IFERROR(INDEX(SessionDB!$H$2:$H$64,MATCH(1,(SessionDB!$B$2:$B$64=2)*(SessionDB!$C$2:$C$64=$A9)*((SessionDB!$I$2:$I$64=$E$3)+(SessionDB!$I$2:$I$64="all")),0)),IFERROR(INDEX(SessionDB!$H$2:$H$64,MATCH(1,(SessionDB!$B$2:$B$64=2)*(SessionDB!$C$2:$C$64<$A9)*(SessionDB!$D$2:$D$64>$A9)*((SessionDB!$I$2:$I$64=$E$3)+(SessionDB!$I$2:$I$64="all")),0)),""))
A10: 11:00 | B10: Panel: Future of Work Lead: Multiple Speakers • Main Hall | I10: =IFERROR(INDEX(SessionDB!$H$2:$H$64,MATCH(1,(SessionDB!$B$2:$B$64=2)*(SessionDB!$C$2:$C$64=$A10)*((SessionDB!$I$2:$I$64=$E$3)+(SessionDB!$I$2:$I$64="all")),0)),IFERROR(INDEX(SessionDB!$H$2:$H$64,MATCH(1,(SessionDB!$B$2:$B$64=2)*(SessionDB!$C$2:$C$64<$A10)*(SessionDB!$D$2:$D$64>$A10)*((SessionDB!$I$2:$I$64=$E$3)+(SessionDB!$I$2:$I$64="all")),0)),""))
A11: 11:30 | I11: =IFERROR(INDEX(SessionDB!$H$2:$H$64,MATCH(1,(SessionDB!$B$2:$B$64=2)*(SessionDB!$C$2:$C$64=$A11)*((SessionDB!$I$2:$I$64=$E$3)+(SessionDB!$I$2:$I$64="all")),0)),IFERROR(INDEX(SessionDB!$H$2:$H$64,MATCH(1,(SessionDB!$B$2:$B$64=2)*(SessionDB!$C$2:$C$64<$A11)*(SessionDB!$D$2:$D$64>$A11)*((SessionDB!$I$2:$I$64=$E$3)+(SessionDB!$I$2:$I$64="all")),0)),""))
A12: 12:00 | B12: Lunch & Networking | I12: =IFERROR(INDEX(SessionDB!$H$2:$H$64,MATCH(1,(SessionDB!$B$2:$B$64=2)*(SessionDB!$C$2:$C$64=$A12)*((SessionDB!$I$2:$I$64=$E$3)+(SessionDB!$I$2:$I$64="all")),0)),IFERROR(INDEX(SessionDB!$H$2:$H$64,MATCH(1,(SessionDB!$B$2:$B$64=2)*(SessionDB!$C$2:$C$64<$A12)*(SessionDB!$D$2:$D$64>$A12)*((SessionDB!$I$2:$I$64=$E$3)+(SessionDB!$I$2:$I$64="all")),0)),""))
A13: 12:30 | I13: =IFERROR(INDEX(SessionDB!$H$2:$H$64,MATCH(1,(SessionDB!$B$2:$B$64=2)*(SessionDB!$C$2:$C$64=$A13)*((SessionDB!$I$2:$I$64=$E$3)+(SessionDB!$I$2:$I$64="all")),0)),IFERROR(INDEX(SessionDB!$H$2:$H$64,MATCH(1,(SessionDB!$B$2:$B$64=2)*(SessionDB!$C$2:$C$64<$A13)*(SessionDB!$D$2:$D$64>$A13)*((SessionDB!$I$2:$I$64=$E$3)+(SessionDB!$I$2:$I$64="all")),0)),""))
A14: 13:00 | C14: Conflict Resolution Lead: Mark Torres • Room A1 | D14: DevOps Practices Lead: Priya Sharma • Room B1 | E14: Accessibility Workshop Lead: Carlos Ruiz • Room C1 | F14: Vendor Management Lead: Nina Petrov • Room D1 | I14: =IFERROR(INDEX(SessionDB!$H$2:$H$64,MATCH(1,(SessionDB!$B$2:$B$64=2)*(SessionDB!$C$2:$C$64=$A14)*((SessionDB!$I$2:$I$64=$E$3)+(SessionDB!$I$2:$I$64="all")),0)),IFERROR(INDEX(SessionDB!$H$2:$H$64,MATCH(1,(SessionDB!$B$2:$B$64=2)*(SessionDB!$C$2:$C$64<$A14)*(SessionDB!$D$2:$D$64>$A14)*((SessionDB!$I$2:$I$64=$E$3)+(SessionDB!$I$2:$I$64="all")),0)),""))
A15: 13:30 | I15: =IFERROR(INDEX(SessionDB!$H$2:$H$64,MATCH(1,(SessionDB!$B$2:$B$64=2)*(SessionDB!$C$2:$C$64=$A15)*((SessionDB!$I$2:$I$64=$E$3)+(SessionDB!$I$2:$I$64="all")),0)),IFERROR(INDEX(SessionDB!$H$2:$H$64,MATCH(1,(SessionDB!$B$2:$B$64=2)*(SessionDB!$C$2:$C$64<$A15)*(SessionDB!$D$2:$D$64>$A15)*((SessionDB!$I$2:$I$64=$E$3)+(SessionDB!$I$2:$I$64="all")),0)),""))
A16: 14:00 | I16: =IFERROR(INDEX(SessionDB!$H$2:$H$64,MATCH(1,(SessionDB!$B$2:$B$64=2)*(SessionDB!$C$2:$C$64=$A16)*((SessionDB!$I$2:$I$64=$E$3)+(SessionDB!$I$2:$I$64="all")),0)),IFERROR(INDEX(SessionDB!$H$2:$H$64,MATCH(1,(SessionDB!$B$2:$B$64=2)*(SessionDB!$C$2:$C$64<$A16)*(SessionDB!$D$2:$D$64>$A16)*((SessionDB!$I$2:$I$64=$E$3)+(SessionDB!$I$2:$I$64="all")),0)),""))
A17: 14:30 | B17: Afternoon Break | I17: =IFERROR(INDEX(SessionDB!$H$2:$H$64,MATCH(1,(SessionDB!$B$2:$B$64=2)*(SessionDB!$C$2:$C$64=$A17)*((SessionDB!$I$2:$I$64=$E$3)+(SessionDB!$I$2:$I$64="all")),0)),IFERROR(INDEX(SessionDB!$H$2:$H$64,MATCH(1,(SessionDB!$B$2:$B$64=2)*(SessionDB!$C$2:$C$64<$A17)*(SessionDB!$D$2:$D$64>$A17)*((SessionDB!$I$2:$I$64=$E$3)+(SessionDB!$I$2:$I$64="all")),0)),""))
A18: 15:00 | C18: Strategic Planning Lead: Tom Bradley • Room A1 | D18: Performance Testing Lead: David Kim • Room B1 | E18: User Research Methods Lead: Yuki Tanaka • Room C1 | F18: Budget Forecasting Lead: Rachel Green • Room D1 | I18: =IFERROR(INDEX(SessionDB!$H$2:$H$64,MATCH(1,(SessionDB!$B$2:$B$64=2)*(SessionDB!$C$2:$C$64=$A18)*((SessionDB!$I$2:$I$64=$E$3)+(SessionDB!$I$2:$I$64="all")),0)),IFERROR(INDEX(SessionDB!$H$2:$H$64,MATCH(1,(SessionDB!$B$2:$B$64=2)*(SessionDB!$C$2:$C$64<$A18)*(SessionDB!$D$2:$D$64>$A18)*((SessionDB!$I$2:$I$64=$E$3)+(SessionDB!$I$2:$I$64="all")),0)),""))
A19: 15:30 | I19: =IFERROR(INDEX(SessionDB!$H$2:$H$64,MATCH(1,(SessionDB!$B$2:$B$64=2)*(SessionDB!$C$2:$C$64=$A19)*((SessionDB!$I$2:$I$64=$E$3)+(SessionDB!$I$2:$I$64="all")),0)),IFERROR(INDEX(SessionDB!$H$2:$H$64,MATCH(1,(SessionDB!$B$2:$B$64=2)*(SessionDB!$C$2:$C$64<$A19)*(SessionDB!$D$2:$D$64>$A19)*((SessionDB!$I$2:$I$64=$E$3)+(SessionDB!$I$2:$I$64="all")),0)),""))
A20: 16:00 | I20: =IFERROR(INDEX(SessionDB!$H$2:$H$64,MATCH(1,(SessionDB!$B$2:$B$64=2)*(SessionDB!$C$2:$C$64=$A20)*((SessionDB!$I$2:$I$64=$E$3)+(SessionDB!$I$2:$I$64="all")),0)),IFERROR(INDEX(SessionDB!$H$2:$H$64,MATCH(1,(SessionDB!$B$2:$B$64=2)*(SessionDB!$C$2:$C$64<$A20)*(SessionDB!$D$2:$D$64>$A20)*((SessionDB!$I$2:$I$64=$E$3)+(SessionDB!$I$2:$I$64="all")),0)),""))
A21: 16:30 | I21: =IFERROR(INDEX(SessionDB!$H$2:$H$64,MATCH(1,(SessionDB!$B$2:$B$64=2)*(SessionDB!$C$2:$C$64=$A21)*((SessionDB!$I$2:$I$64=$E$3)+(SessionDB!$I$2:$I$64="all")),0)),IFERROR(INDEX(SessionDB!$H$2:$H$64,MATCH(1,(SessionDB!$B$2:$B$64=2)*(SessionDB!$C$2:$C$64<$A21)*(SessionDB!$D$2:$D$64>$A21)*((SessionDB!$I$2:$I$64=$E$3)+(SessionDB!$I$2:$I$64="all")),0)),""))
A22: 17:00 | I22: =IFERROR(INDEX(SessionDB!$H$2:$H$64,MATCH(1,(SessionDB!$B$2:$B$64=2)*(SessionDB!$C$2:$C$64=$A22)*((SessionDB!$I$2:$I$64=$E$3)+(SessionDB!$I$2:$I$64="all")),0)),IFERROR(INDEX(SessionDB!$H$2:$H$64,MATCH(1,(SessionDB!$B$2:$B$64=2)*(SessionDB!$C$2:$C$64<$A22)*(SessionDB!$D$2:$D$64>$A22)*((SessionDB!$I$2:$I$64=$E$3)+(SessionDB!$I$2:$I$64="all")),0)),""))
A23: 17:30 | I23: =IFERROR(INDEX(SessionDB!$H$2:$H$64,MATCH(1,(SessionDB!$B$2:$B$64=2)*(SessionDB!$C$2:$C$64=$A23)*((SessionDB!$I$2:$I$64=$E$3)+(SessionDB!$I$2:$I$64="all")),0)),IFERROR(INDEX(SessionDB!$H$2:$H$64,MATCH(1,(SessionDB!$B$2:$B$64=2)*(SessionDB!$C$2:$C$64<$A23)*(SessionDB!$D$2:$D$64>$A23)*((SessionDB!$I$2:$I$64=$E$3)+(SessionDB!$I$2:$I$64="all")),0)),""))
A25: Tracks: Overall, Leadership, Technical, Design Thinking, Operations | Generated: 08 Mar 2026 13:00

Sheet Day 3
A1: DAY 3: Wed Mar 11
A2: REFRESHED: 08 Mar 2026 13:00 | 4 tracks + Overall | Workshop 2026
A3: TIME | B3: OVERALL | C3: LEADERSHIP | D3: TECHNICAL | E3: DESIGN THINKING | F3: OPERATIONS
A4: 08:00 | I4: =IFERROR(INDEX(SessionDB!$H$2:$H$64,MATCH(1,(SessionDB!$B$2:$B$64=3)*(SessionDB!$C$2:$C$64=$A4)*((SessionDB!$I$2:$I$64=$E$3)+(SessionDB!$I$2:$I$64="all")),0)),IFERROR(INDEX(SessionDB!$H$2:$H$64,MATCH(1,(SessionDB!$B$2:$B$64=3)*(SessionDB!$C$2:$C$64<$A4)*(SessionDB!$D$2:$D$64>$A4)*((SessionDB!$I$2:$I$64=$E$3)+(SessionDB!$I$2:$I$64="all")),0)),""))
A5: 08:30 | I5: =IFERROR(INDEX(SessionDB!$H$2:$H$64,MATCH(1,(SessionDB!$B$2:$B$64=3)*(SessionDB!$C$2:$C$64=$A5)*((SessionDB!$I$2:$I$64=$E$3)+(SessionDB!$I$2:$I$64="all")),0)),IFERROR(INDEX(SessionDB!$H$2:$H$64,MATCH(1,(SessionDB!$B$2:$B$64=3)*(SessionDB!$C$2:$C$64<$A5)*(SessionDB!$D$2:$D$64>$A5)*((SessionDB!$I$2:$I$64=$E$3)+(SessionDB!$I$2:$I$64="all")),0)),""))
A6: 09:00 | B6: Midweek Keynote Lead: Dr. Sarah Chen • Main Hall | I6: =IFERROR(INDEX(SessionDB!$H$2:$H$64,MATCH(1,(SessionDB!$B$2:$B$64=3)*(SessionDB!$C$2:$C$64=$A6)*((SessionDB!$I$2:$I$64=$E$3)+(SessionDB!$I$2:$I$64="all")),0)),IFERROR(INDEX(SessionDB!$H$2:$H$64,MATCH(1,(SessionDB!$B$2:$B$64=3)*(SessionDB!$C$2:$C$64<$A6)*(SessionDB!$D$2:$D$64>$A6)*((SessionDB!$I$2:$I$64=$E$3)+(SessionDB!$I$2:$I$64="all")),0)),""))
A7: 09:30 | I7: =IFERROR(INDEX(SessionDB!$H$2:$H$64,MATCH(1,(SessionDB!$B$2:$B$64=3)*(SessionDB!$C$2:$C$64=$A7)*((SessionDB!$I$2:$I$64=$E$3)+(SessionDB!$I$2:$I$64="all")),0)),IFERROR(INDEX(SessionDB!$H$2:$H$64,MATCH(1,(SessionDB!$B$2:$B$64=3)*(SessionDB!$C$2:$C$64<$A7)*(SessionDB!$D$2:$D$64>$A7)*((SessionDB!$I$2:$I$64=$E$3)+(SessionDB!$I$2:$I$64="all")),0)),""))
A8: 10:00 | B8: Morning Break | I8: =IFERROR(INDEX(SessionDB!$H$2:$H$64,MATCH(1,(SessionDB!$B$2:$B$64=3)*(SessionDB!$C$2:$C$64=$A8)*((SessionDB!$I$2:$I$64=$E$3)+(SessionDB!$I$2:$I$64="all")),0)),IFERROR(INDEX(SessionDB!$H$2:$H$64,MATCH(1,(SessionDB!$B$2:$B$64=3)*(SessionDB!$C$2:$C$64<$A8)*(SessionDB!$D$2:$D$64>$A8)*((SessionDB!$I$2:$I$64=$E$3)+(SessionDB!$I$2:$I$64="all")),0)),""))
A9: 10:30 | C9: Cross-Team Collaboration Lead: Aisha Johnson • Room A1 | D9: AI/ML Integration Lead: Wei Zhang • Room B1 | E9: Workshop Facilitation Lead: Lena Müller • Room C1 | F9: Incident Response Lead: Alex Novak • Room D1 | I9: =IFERROR(INDEX(SessionDB!$H$2:$H$64,MATCH(1,(SessionDB!$B$2:$B$64=3)*(SessionDB!$C$2:$C$64=$A9)*((SessionDB!$I$2:$I$64=$E$3)+(SessionDB!$I$2:$I$64="all")),0)),IFERROR(INDEX(SessionDB!$H$2:$H$64,MATCH(1,(SessionDB!$B$2:$B$64=3)*(SessionDB!$C$2:$C$64<$A9)*(SessionDB!$D$2:$D$64>$A9)*((SessionDB!$I$2:$I$64=$E$3)+(SessionDB!$I$2:$I$64="all")),0)),""))
A10: 11:00 | I10: =IFERROR(INDEX(SessionDB!$H$2:$H$64,MATCH(1,(SessionDB!$B$2:$B$64=3)*(SessionDB!$C$2:$C$64=$A10)*((SessionDB!$I$2:$I$64=$E$3)+(SessionDB!$I$2:$I$64="all")),0)),IFERROR(INDEX(SessionDB!$H$2:$H$64,MATCH(1,(SessionDB!$B$2:$B$64=3)*(SessionDB!$C$2:$C$64<$A10)*(SessionDB!$D$2:$D$64>$A10)*((SessionDB!$I$2:$I$64=$E$3)+(SessionDB!$I$2:$I$64="all")),0)),""))
A11: 11:30 | I11: =IFERROR(INDEX(SessionDB!$H$2:$H$64,MATCH(1,(SessionDB!$B$2:$B$64=3)*(SessionDB!$C$2:$C$64=$A11)*((SessionDB!$I$2:$I$64=$E$3)+(SessionDB!$I$2:$I$64="all")),0)),IFERROR(INDEX(SessionDB!$H$2:$H$64,MATCH(1,(SessionDB!$B$2:$B$64=3)*(SessionDB!$C$2:$C$64<$A11)*(SessionDB!$D$2:$D$64>$A11)*((SessionDB!$I$2:$I$64=$E$3)+(SessionDB!$I$2:$I$64="all")),0)),""))
A12: 12:00 | B12: Lunch & Networking | I12: =IFERROR(INDEX(SessionDB!$H$2:$H$64,MATCH(1,(SessionDB!$B$2:$B$64=3)*(SessionDB!$C$2:$C$64=$A12)*((SessionDB!$I$2:$I$64=$E$3)+(SessionDB!$I$2:$I$64="all")),0)),IFERROR(INDEX(SessionDB!$H$2:$H$64,MATCH(1,(SessionDB!$B$2:$B$64=3)*(SessionDB!$C$2:$C$64<$A12)*(SessionDB!$D$2:$D$64>$A12)*((SessionDB!$I$2:$I$64=$E$3)+(SessionDB!$I$2:$I$64="all")),0)),""))
A13: 12:30 | I13: =IFERROR(INDEX(SessionDB!$H$2:$H$64,MATCH(1,(SessionDB!$B$2:$B$64=3)*(SessionDB!$C$2:$C$64=$A13)*((SessionDB!$I$2:$I$64=$E$3)+(SessionDB!$I$2:$I$64="all")),0)),IFERROR(INDEX(SessionDB!$H$2:$H$64,MATCH(1,(SessionDB!$B$2:$B$64=3)*(SessionDB!$C$2:$C$64<$A13)*(SessionDB!$D$2:$D$64>$A13)*((SessionDB!$I$2:$I$64=$E$3)+(SessionDB!$I$2:$I$64="all")),0)),""))
A14: 13:00 | B14: Cross-Track Hackathon Lead: All Facilitators • All Rooms | I14: =IFERROR(INDEX(SessionDB!$H$2:$H$64,MATCH(1,(SessionDB!$B$2:$B$64=3)*(SessionDB!$C$2:$C$64=$A14)*((SessionDB!$I$2:$I$64=$E$3)+(SessionDB!$I$2:$I$64="all")),0)),IFERROR(INDEX(SessionDB!$H$2:$H$64,MATCH(1,(SessionDB!$B$2:$B$64=3)*(SessionDB!$C$2:$C$64<$A14)*(SessionDB!$D$2:$D$64>$A14)*((SessionDB!$I$2:$I$64=$E$3)+(SessionDB!$I$2:$I$64="all")),0)),""))
A15: 13:30 | I15: =IFERROR(INDEX(SessionDB!$H$2:$H$64,MATCH(1,(SessionDB!$B$2:$B$64=3)*(SessionDB!$C$2:$C$64=$A15)*((SessionDB!$I$2:$I$64=$E$3)+(SessionDB!$I$2:$I$64="all")),0)),IFERROR(INDEX(SessionDB!$H$2:$H$64,MATCH(1,(SessionDB!$B$2:$B$64=3)*(SessionDB!$C$2:$C$64<$A15)*(SessionDB!$D$2:$D$64>$A15)*((SessionDB!$I$2:$I$64=$E$3)+(SessionDB!$I$2:$I$64="all")),0)),""))
A16: 14:00 | I16: =IFERROR(INDEX(SessionDB!$H$2:$H$64,MATCH(1,(SessionDB!$B$2:$B$64=3)*(SessionDB!$C$2:$C$64=$A16)*((SessionDB!$I$2:$I$64=$E$3)+(SessionDB!$I$2:$I$64="all")),0)),IFERROR(INDEX(SessionDB!$H$2:$H$64,MATCH(1,(SessionDB!$B$2:$B$64=3)*(SessionDB!$C$2:$C$64<$A16)*(SessionDB!$D$2:$D$64>$A16)*((SessionDB!$I$2:$I$64=$E$3)+(SessionDB!$I$2:$I$64="all")),0)),""))
A17: 14:30 | I17: =IFERROR(INDEX(SessionDB!$H$2:$H$64,MATCH(1,(SessionDB!$B$2:$B$64=3)*(SessionDB!$C$2:$C$64=$A17)*((SessionDB!$I$2:$I$64=$E$3)+(SessionDB!$I$2:$I$64="all")),0)),IFERROR(INDEX(SessionDB!$H$2:$H$64,MATCH(1,(SessionDB!$B$2:$B$64=3)*(SessionDB!$C$2:$C$64<$A17)*(SessionDB!$D$2:$D$64>$A17)*((SessionDB!$I$2:$I$64=$E$3)+(SessionDB!$I$2:$I$64="all")),0)),""))
A18: 15:00 | I18: =IFERROR(INDEX(SessionDB!$H$2:$H$64,MATCH(1,(SessionDB!$B$2:$B$64=3)*(SessionDB!$C$2:$C$64=$A18)*((SessionDB!$I$2:$I$64=$E$3)+(SessionDB!$I$2:$I$64="all")),0)),IFERROR(INDEX(SessionDB!$H$2:$H$64,MATCH(1,(SessionDB!$B$2:$B$64=3)*(SessionDB!$C$2:$C$64<$A18)*(SessionDB!$D$2:$D$64>$A18)*((SessionDB!$I$2:$I$64=$E$3)+(SessionDB!$I$2:$I$64="all")),0)),""))
A19: 15:30 | I19: =IFERROR(INDEX(SessionDB!$H$2:$H$64,MATCH(1,(SessionDB!$B$2:$B$64=3)*(SessionDB!$C$2:$C$64=$A19)*((SessionDB!$I$2:$I$64=$E$3)+(SessionDB!$I$2:$I$64="all")),0)),IFERROR(INDEX(SessionDB!$H$2:$H$64,MATCH(1,(SessionDB!$B$2:$B$64=3)*(SessionDB!$C$2:$C$64<$A19)*(SessionDB!$D$2:$D$64>$A19)*((SessionDB!$I$2:$I$64=$E$3)+(SessionDB!$I$2:$I$64="all")),0)),""))
A20: 16:00 | I20: =IFERROR(INDEX(SessionDB!$H$2:$H$64,MATCH(1,(SessionDB!$B$2:$B$64=3)*(SessionDB!$C$2:$C$64=$A20)*((SessionDB!$I$2:$I$64=$E$3)+(SessionDB!$I$2:$I$64="all")),0)),IFERROR(INDEX(SessionDB!$H$2:$H$64,MATCH(1,(SessionDB!$B$2:$B$64=3)*(SessionDB!$C$2:$C$64<$A20)*(SessionDB!$D$2:$D$64>$A20)*((SessionDB!$I$2:$I$64=$E$3)+(SessionDB!$I$2:$I$64="all")),0)),""))
A21: 16:30 | I21: =IFERROR(INDEX(SessionDB!$H$2:$H$64,MATCH(1,(SessionDB!$B$2:$B$64=3)*(SessionDB!$C$2:$C$64=$A21)*((SessionDB!$I$2:$I$64=$E$3)+(SessionDB!$I$2:$I$64="all")),0)),IFERROR(INDEX(SessionDB!$H$2:$H$64,MATCH(1,(SessionDB!$B$2:$B$64=3)*(SessionDB!$C$2:$C$64<$A21)*(SessionDB!$D$2:$D$64>$A21)*((SessionDB!$I$2:$I$64=$E$3)+(SessionDB!$I$2:$I$64="all")),0)),""))
A22: 17:00 | I22: =IFERROR(INDEX(SessionDB!$H$2:$H$64,MATCH(1,(SessionDB!$B$2:$B$64=3)*(SessionDB!$C$2:$C$64=$A22)*((SessionDB!$I$2:$I$64=$E$3)+(SessionDB!$I$2:$I$64="all")),0)),IFERROR(INDEX(SessionDB!$H$2:$H$64,MATCH(1,(SessionDB!$B$2:$B$64=3)*(SessionDB!$C$2:$C$64<$A22)*(SessionDB!$D$2:$D$64>$A22)*((SessionDB!$I$2:$I$64=$E$3)+(SessionDB!$I$2:$I$64="all")),0)),""))
A23: 17:30 | I23: =IFERROR(INDEX(SessionDB!$H$2:$H$64,MATCH(1,(SessionDB!$B$2:$B$64=3)*(SessionDB!$C$2:$C$64=$A23)*((SessionDB!$I$2:$I$64=$E$3)+(SessionDB!$I$2:$I$64="all")),0)),IFERROR(INDEX(SessionDB!$H$2:$H$64,MATCH(1,(SessionDB!$B$2:$B$64=3)*(SessionDB!$C$2:$C$64<$A23)*(SessionDB!$D$2:$D$64>$A23)*((SessionDB!$I$2:$I$64=$E$3)+(SessionDB!$I$2:$I$64="all")),0)),""))
A25: Tracks: Overall, Leadership, Technical, Design Thinking, Operations | Generated: 08 Mar 2026 13:00

Sheet Day 4
A1: DAY 4: Thu Mar 12
A2: REFRESHED: 08 Mar 2026 13:00 | 4 tracks + Overall | Workshop 2026
A3: TIME | B3: OVERALL | C3: LEADERSHIP | D3: TECHNICAL | E3: DESIGN THINKING | F3: OPERATIONS
A4: 08:00 | I4: =IFERROR(INDEX(SessionDB!$H$2:$H$64,MATCH(1,(SessionDB!$B$2:$B$64=4)*(SessionDB!$C$2:$C$64=$A4)*((SessionDB!$I$2:$I$64=$E$3)+(SessionDB!$I$2:$I$64="all")),0)),IFERROR(INDEX(SessionDB!$H$2:$H$64,MATCH(1,(SessionDB!$B$2:$B$64=4)*(SessionDB!$C$2:$C$64<$A4)*(SessionDB!$D$2:$D$64>$A4)*((SessionDB!$I$2:$I$64=$E$3)+(SessionDB!$I$2:$I$64="all")),0)),""))
A5: 08:30 | I5: =IFERROR(INDEX(SessionDB!$H$2:$H$64,MATCH(1,(SessionDB!$B$2:$B$64=4)*(SessionDB!$C$2:$C$64=$A5)*((SessionDB!$I$2:$I$64=$E$3)+(SessionDB!$I$2:$I$64="all")),0)),IFERROR(INDEX(SessionDB!$H$2:$H$64,MATCH(1,(SessionDB!$B$2:$B$64=4)*(SessionDB!$C$2:$C$64<$A5)*(SessionDB!$D$2:$D$64>$A5)*((SessionDB!$I$2:$I$64=$E$3)+(SessionDB!$I$2:$I$64="all")),0)),""))
A6: 09:00 | C6: Coaching Skills Lead: Mark Torres • Room A1 | D6: System Architecture Lead: David Kim • Room B1 | E6: Data Visualization Lead: Carlos Ruiz • Room C1 | F6: Change Management Lead: James Wright • Room D1 | I6: =IFERROR(INDEX(SessionDB!$H$2:$H$64,MATCH(1,(SessionDB!$B$2:$B$64=4)*(SessionDB!$C$2:$C$64=$A6)*((SessionDB!$I$2:$I$64=$E$3)+(SessionDB!$I$2:$I$64="all")),0)),IFERROR(INDEX(SessionDB!$H$2:$H$64,MATCH(1,(SessionDB!$B$2:$B$64=4)*(SessionDB!$C$2:$C$64<$A6)*(SessionDB!$D$2:$D$64>$A6)*((SessionDB!$I$2:$I$64=$E$3)+(SessionDB!$I$2:$I$64="all")),0)),""))
A7: 09:30 | I7: =IFERROR(INDEX(SessionDB!$H$2:$H$64,MATCH(1,(SessionDB!$B$2:$B$64=4)*(SessionDB!$C$2:$C$64=$A7)*((SessionDB!$I$2:$I$64=$E$3)+(SessionDB!$I$2:$I$64="all")),0)),IFERROR(INDEX(SessionDB!$H$2:$H$64,MATCH(1,(SessionDB!$B$2:$B$64=4)*(SessionDB!$C$2:$C$64<$A7)*(SessionDB!$D$2:$D$64>$A7)*((SessionDB!$I$2:$I$64=$E$3)+(SessionDB!$I$2:$I$64="all")),0)),""))
A8: 10:00 | I8: =IFERROR(INDEX(SessionDB!$H$2:$H$64,MATCH(1,(SessionDB!$B$2:$B$64=4)*(SessionDB!$C$2:$C$64=$A8)*((SessionDB!$I$2:$I$64=$E$3)+(SessionDB!$I$2:$I$64="all")),0)),IFERROR(INDEX(SessionDB!$H$2:$H$64,MATCH(1,(SessionDB!$B$2:$B$64=4)*(SessionDB!$C$2:$C$64<$A8)*(SessionDB!$D$2:$D$64>$A8)*((SessionDB!$I$2:$I$64=$E$3)+(SessionDB!$I$2:$I$64="all")),0)),""))
A9: 10:30 | B9: Morning Break | I9: =IFERROR(INDEX(SessionDB!$H$2:$H$64,MATCH(1,(SessionDB!$B$2:$B$64=4)*(SessionDB!$C$2:$C$64=$A9)*((SessionDB!$I$2:$I$64=$E$3)+(SessionDB!$I$2:$I$64="all")),0)),IFERROR(INDEX(SessionDB!$H$2:$H$64,MATCH(1,(SessionDB!$B$2:$B$64=4)*(SessionDB!$C$2:$C$64<$A9)*(SessionDB!$D$2:$D$64>$A9)*((SessionDB!$I$2:$I$64=$E$3)+(SessionDB!$I$2:$I$64="all")),0)),""))
A10: 11:00 | C10: Presentation Mastery Lead: Tom Bradley • Room A1 | D10: Testing Strategies Lead: Priya Sharma • Room B1 | E10: Design Critiques Lead: Yuki Tanaka • Room C1 | F10: Process Automation Lead: Nina Petrov • Room D1 | I10: =IFERROR(INDEX(SessionDB!$H$2:$H$64,MATCH(1,(SessionDB!$B$2:$B$64=4)*(SessionDB!$C$2:$C$64=$A10)*((SessionDB!$I$2:$I$64=$E$3)+(SessionDB!$I$2:$I$64="all")),0)),IFERROR(INDEX(SessionDB!$H$2:$H$64,MATCH(1,(SessionDB!$B$2:$B$64=4)*(SessionDB!$C$2:$C$64<$A10)*(SessionDB!$D$2:$D$64>$A10)*((SessionDB!$I$2:$I$64=$E$3)+(SessionDB!$I$2:$I$64="all")),0)),""))
A11: 11:30 | I11: =IFERROR(INDEX(SessionDB!$H$2:$H$64,MATCH(1,(SessionDB!$B$2:$B$64=4)*(SessionDB!$C$2:$C$64=$A11)*((SessionDB!$I$2:$I$64=$E$3)+(SessionDB!$I$2:$I$64="all")),0)),IFERROR(INDEX(SessionDB!$H$2:$H$64,MATCH(1,(SessionDB!$B$2:$B$64=4)*(SessionDB!$C$2:$C$64<$A11)*(SessionDB!$D$2:$D$64>$A11)*((SessionDB!$I$2:$I$64=$E$3)+(SessionDB!$I$2:$I$64="all")),0)),""))
A12: 12:00 | I12: =IFERROR(INDEX(SessionDB!$H$2:$H$64,MATCH(1,(SessionDB!$B$2:$B$64=4)*(SessionDB!$C$2:$C$64=$A12)*((SessionDB!$I$2:$I$64=$E$3)+(SessionDB!$I$2:$I$64="all")),0)),IFERROR(INDEX(SessionDB!$H$2:$H$64,MATCH(1,(SessionDB!$B$2:$B$64=4)*(SessionDB!$C$2:$C$64<$A12)*(SessionDB!$D$2:$D$64>$A12)*((SessionDB!$I$2:$I$64=$E$3)+(SessionDB!$I$2:$I$64="all")),0)),""))
A13: 12:30 | B13: Lunch & Networking | I13: =IFERROR(INDEX(SessionDB!$H$2:$H$64,MATCH(1,(SessionDB!$B$2:$B$64=4)*(SessionDB!$C$2:$C$64=$A13)*((SessionDB!$I$2:$I$64=$E$3)+(SessionDB!$I$2:$I$64="all")),0)),IFERROR(INDEX(SessionDB!$H$2:$H$64,MATCH(1,(SessionDB!$B$2:$B$64=4)*(SessionDB!$C$2:$C$64<$A13)*(SessionDB!$D$2:$D$64>$A13)*((SessionDB!$I$2:$I$64=$E$3)+(SessionDB!$I$2:$I$64="all")),0)),""))
A14: 13:00 | I14: =IFERROR(INDEX(SessionDB!$H$2:$H$64,MATCH(1,(SessionDB!$B$2:$B$64=4)*(SessionDB!$C$2:$C$64=$A14)*((SessionDB!$I$2:$I$64=$E$3)+(SessionDB!$I$2:$I$64="all")),0)),IFERROR(INDEX(SessionDB!$H$2:$H$64,MATCH(1,(SessionDB!$B$2:$B$64=4)*(SessionDB!$C$2:$C$64<$A14)*(SessionDB!$D$2:$D$64>$A14)*((SessionDB!$I$2:$I$64=$E$3)+(SessionDB!$I$2:$I$64="all")),0)),""))
A15: 13:30 | C15: Succession Planning Lead: Aisha Johnson • Room A1 | D15: Code Review Culture Lead: Alex Novak • Room B1 | E15: Design Handoff Lead: Lena Müller • Room C1 | F15: KPI Dashboards Lead: Rachel Green • Room D1 | I15: =IFERROR(INDEX(SessionDB!$H$2:$H$64,MATCH(1,(SessionDB!$B$2:$B$64=4)*(SessionDB!$C$2:$C$64=$A15)*((SessionDB!$I$2:$I$64=$E$3)+(SessionDB!$I$2:$I$64="all")),0)),IFERROR(INDEX(SessionDB!$H$2:$H$64,MATCH(1,(SessionDB!$B$2:$B$64=4)*(SessionDB!$C$2:$C$64<$A15)*(SessionDB!$D$2:$D$64>$A15)*((SessionDB!$I$2:$I$64=$E$3)+(SessionDB!$I$2:$I$64="all")),0)),""))
A16: 14:00 | I16: =IFERROR(INDEX(SessionDB!$H$2:$H$64,MATCH(1,(SessionDB!$B$2:$B$64=4)*(SessionDB!$C$2:$C$64=$A16)*((SessionDB!$I$2:$I$64=$E$3)+(SessionDB!$I$2:$I$64="all")),0)),IFERROR(INDEX(SessionDB!$H$2:$H$64,MATCH(1,(SessionDB!$B$2:$B$64=4)*(SessionDB!$C$2:$C$64<$A16)*(SessionDB!$D$2:$D$64>$A16)*((SessionDB!$I$2:$I$64=$E$3)+(SessionDB!$I$2:$I$64="all")),0)),""))
A17: 14:30 | I17: =IFERROR(INDEX(SessionDB!$H$2:$H$64,MATCH(1,(SessionDB!$B$2:$B$64=4)*(SessionDB!$C$2:$C$64=$A17)*((SessionDB!$I$2:$I$64=$E$3)+(SessionDB!$I$2:$I$64="all")),0)),IFERROR(INDEX(SessionDB!$H$2:$H$64,MATCH(1,(SessionDB!$B$2:$B$64=4)*(SessionDB!$C$2:$C$64<$A17)*(SessionDB!$D$2:$D$64>$A17)*((SessionDB!$I$2:$I$64=$E$3)+(SessionDB!$I$2:$I$64="all")),0)),""))
A18: 15:00 | B18: Afternoon Break | I18: =IFERROR(INDEX(SessionDB!$H$2:$H$64,MATCH(1,(SessionDB!$B$2:$B$64=4)*(SessionDB!$C$2:$C$64=$A18)*((SessionDB!$I$2:$I$64=$E$3)+(SessionDB!$I$2:$I$64="all")),0)),IFERROR(INDEX(SessionDB!$H$2:$H$64,MATCH(1,(SessionDB!$B$2:$B$64=4)*(SessionDB!$C$2:$C$64<$A18)*(SessionDB!$D$2:$D$64>$A18)*((SessionDB!$I$2:$I$64=$E$3)+(SessionDB!$I$2:$I$64="all")),0)),""))
A19: 15:30 | B19: Hackathon Presentations Lead: Selected Teams • Main Hall | I19: =IFERROR(INDEX(SessionDB!$H$2:$H$64,MATCH(1,(SessionDB!$B$2:$B$64=4)*(SessionDB!$C$2:$C$64=$A19)*((SessionDB!$I$2:$I$64=$E$3)+(SessionDB!$I$2:$I$64="all")),0)),IFERROR(INDEX(SessionDB!$H$2:$H$64,MATCH(1,(SessionDB!$B$2:$B$64=4)*(SessionDB!$C$2:$C$64<$A19)*(SessionDB!$D$2:$D$64>$A19)*((SessionDB!$I$2:$I$64=$E$3)+(SessionDB!$I$2:$I$64="all")),0)),""))
A20: 16:00 | I20: =IFERROR(INDEX(SessionDB!$H$2:$H$64,MATCH(1,(SessionDB!$B$2:$B$64=4)*(SessionDB!$C$2:$C$64=$A20)*((SessionDB!$I$2:$I$64=$E$3)+(SessionDB!$I$2:$I$64="all")),0)),IFERROR(INDEX(SessionDB!$H$2:$H$64,MATCH(1,(SessionDB!$B$2:$B$64=4)*(SessionDB!$C$2:$C$64<$A20)*(SessionDB!$D$2:$D$64>$A20)*((SessionDB!$I$2:$I$64=$E$3)+(SessionDB!$I$2:$I$64="all")),0)),""))
A21: 16:30 | I21: =IFERROR(INDEX(SessionDB!$H$2:$H$64,MATCH(1,(SessionDB!$B$2:$B$64=4)*(SessionDB!$C$2:$C$64=$A21)*((SessionDB!$I$2:$I$64=$E$3)+(SessionDB!$I$2:$I$64="all")),0)),IFERROR(INDEX(SessionDB!$H$2:$H$64,MATCH(1,(SessionDB!$B$2:$B$64=4)*(SessionDB!$C$2:$C$64<$A21)*(SessionDB!$D$2:$D$64>$A21)*((SessionDB!$I$2:$I$64=$E$3)+(SessionDB!$I$2:$I$64="all")),0)),""))
A22: 17:00 | I22: =IFERROR(INDEX(SessionDB!$H$2:$H$64,MATCH(1,(SessionDB!$B$2:$B$64=4)*(SessionDB!$C$2:$C$64=$A22)*((SessionDB!$I$2:$I$64=$E$3)+(SessionDB!$I$2:$I$64="all")),0)),IFERROR(INDEX(SessionDB!$H$2:$H$64,MATCH(1,(SessionDB!$B$2:$B$64=4)*(SessionDB!$C$2:$C$64<$A22)*(SessionDB!$D$2:$D$64>$A22)*((SessionDB!$I$2:$I$64=$E$3)+(SessionDB!$I$2:$I$64="all")),0)),""))
A23: 17:30 | I23: =IFERROR(INDEX(SessionDB!$H$2:$H$64,MATCH(1,(SessionDB!$B$2:$B$64=4)*(SessionDB!$C$2:$C$64=$A23)*((SessionDB!$I$2:$I$64=$E$3)+(SessionDB!$I$2:$I$64="all")),0)),IFERROR(INDEX(SessionDB!$H$2:$H$64,MATCH(1,(SessionDB!$B$2:$B$64=4)*(SessionDB!$C$2:$C$64<$A23)*(SessionDB!$D$2:$D$64>$A23)*((SessionDB!$I$2:$I$64=$E$3)+(SessionDB!$I$2:$I$64="all")),0)),""))
A25: Tracks: Overall, Leadership, Technical, Design Thinking, Operations | Generated: 08 Mar 2026 13:00

Sheet Day 5
A1: DAY 5: Fri Mar 13
A2: REFRESHED: 08 Mar 2026 13:00 | 4 tracks + Overall | Workshop 2026
A3: TIME | B3: OVERALL | C3: LEADERSHIP | D3: TECHNICAL | E3: DESIGN THINKING | F3: OPERATIONS
A4: 08:00 | I4: =IFERROR(INDEX(SessionDB!$H$2:$H$64,MATCH(1,(SessionDB!$B$2:$B$64=5)*(SessionDB!$C$2:$C$64=$A4)*((SessionDB!$I$2:$I$64=$E$3)+(SessionDB!$I$2:$I$64="all")),0)),IFERROR(INDEX(SessionDB!$H$2:$H$64,MATCH(1,(SessionDB!$B$2:$B$64=5)*(SessionDB!$C$2:$C$64<$A4)*(SessionDB!$D$2:$D$64>$A4)*((SessionDB!$I$2:$I$64=$E$3)+(SessionDB!$I$2:$I$64="all")),0)),""))
A5: 08:30 | I5: =IFERROR(INDEX(SessionDB!$H$2:$H$64,MATCH(1,(SessionDB!$B$2:$B$64=5)*(SessionDB!$C$2:$C$64=$A5)*((SessionDB!$I$2:$I$64=$E$3)+(SessionDB!$I$2:$I$64="all")),0)),IFERROR(INDEX(SessionDB!$H$2:$H$64,MATCH(1,(SessionDB!$B$2:$B$64=5)*(SessionDB!$C$2:$C$64<$A5)*(SessionDB!$D$2:$D$64>$A5)*((SessionDB!$I$2:$I$64=$E$3)+(SessionDB!$I$2:$I$64="all")),0)),""))
A6: 09:00 | C6: Personal Action Plans Lead: Mark Torres • Room A1 | D6: Tech Roadmapping Lead: David Kim • Room B1 | E6: Portfolio Building Lead: Carlos Ruiz • Room C1 | F6: Continuous Improvement Lead: James Wright • Room D1 | I6: =IFERROR(INDEX(SessionDB!$H$2:$H$64,MATCH(1,(SessionDB!$B$2:$B$64=5)*(SessionDB!$C$2:$C$64=$A6)*((SessionDB!$I$2:$I$64=$E$3)+(SessionDB!$I$2:$I$64="all")),0)),IFERROR(INDEX(SessionDB!$H$2:$H$64,MATCH(1,(SessionDB!$B$2:$B$64=5)*(SessionDB!$C$2:$C$64<$A6)*(SessionDB!$D$2:$D$64>$A6)*((SessionDB!$I$2:$I$64=$E$3)+(SessionDB!$I$2:$I$64="all")),0)),""))
A7: 09:30 | I7: =IFERROR(INDEX(SessionDB!$H$2:$H$64,MATCH(1,(SessionDB!$B$2:$B$64=5)*(SessionDB!$C$2:$C$64=$A7)*((SessionDB!$I$2:$I$64=$E$3)+(SessionDB!$I$2:$I$64="all")),0)),IFERROR(INDEX(SessionDB!$H$2:$H$64,MATCH(1,(SessionDB!$B$2:$B$64=5)*(SessionDB!$C$2:$C$64<$A7)*(SessionDB!$D$2:$D$64>$A7)*((SessionDB!$I$2:$I$64=$E$3)+(SessionDB!$I$2:$I$64="all")),0)),""))
A8: 10:00 | I8: =IFERROR(INDEX(SessionDB!$H$2:$H$64,MATCH(1,(SessionDB!$B$2:$B$64=5)*(SessionDB!$C$2:$C$64=$A8)*((SessionDB!$I$2:$I$64=$E$3)+(SessionDB!$I$2:$I$64="all")),0)),IFERROR(INDEX(SessionDB!$H$2:$H$64,MATCH(1,(SessionDB!$B$2:$B$64=5)*(SessionDB!$C$2:$C$64<$A8)*(SessionDB!$D$2:$D$64>$A8)*((SessionDB!$I$2:$I$64=$E$3)+(SessionDB!$I$2:$I$64="all")),0)),""))
A9: 10:30 | B9: Morning Break | I9: =IFERROR(INDEX(SessionDB!$H$2:$H$64,MATCH(1,(SessionDB!$B$2:$B$64=5)*(SessionDB!$C$2:$C$64=$A9)*((SessionDB!$I$2:$I$64=$E$3)+(SessionDB!$I$2:$I$64="all")),0)),IFERROR(INDEX(SessionDB!$H$2:$H$64,MATCH(1,(SessionDB!$B$2:$B$64=5)*(SessionDB!$C$2:$C$64<$A9)*(SessionDB!$D$2:$D$64>$A9)*((SessionDB!$I$2:$I$64=$E$3)+(SessionDB!$I$2:$I$64="all")),0)),""))
A10: 11:00 | B10: Track Showcases Lead: Track Leads • Main Hall | I10: =IFERROR(INDEX(SessionDB!$H$2:$H$64,MATCH(1,(SessionDB!$B$2:$B$64=5)*(SessionDB!$C$2:$C$64=$A10)*((SessionDB!$I$2:$I$64=$E$3)+(SessionDB!$I$2:$I$64="all")),0)),IFERROR(INDEX(SessionDB!$H$2:$H$64,MATCH(1,(SessionDB!$B$2:$B$64=5)*(SessionDB!$C$2:$C$64<$A10)*(SessionDB!$D$2:$D$64>$A10)*((SessionDB!$I$2:$I$64=$E$3)+(SessionDB!$I$2:$I$64="all")),0)),""))
A11: 11:30 | I11: =IFERROR(INDEX(SessionDB!$H$2:$H$64,MATCH(1,(SessionDB!$B$2:$B$64=5)*(SessionDB!$C$2:$C$64=$A11)*((SessionDB!$I$2:$I$64=$E$3)+(SessionDB!$I$2:$I$64="all")),0)),IFERROR(INDEX(SessionDB!$H$2:$H$64,MATCH(1,(SessionDB!$B$2:$B$64=5)*(SessionDB!$C$2:$C$64<$A11)*(SessionDB!$D$2:$D$64>$A11)*((SessionDB!$I$2:$I$64=$E$3)+(SessionDB!$I$2:$I$64="all")),0)),""))
A12: 12:00 | B12: Farewell Lunch | I12: =IFERROR(INDEX(SessionDB!$H$2:$H$64,MATCH(1,(SessionDB!$B$2:$B$64=5)*(SessionDB!$C$2:$C$64=$A12)*((SessionDB!$I$2:$I$64=$E$3)+(SessionDB!$I$2:$I$64="all")),0)),IFERROR(INDEX(SessionDB!$H$2:$H$64,MATCH(1,(SessionDB!$B$2:$B$64=5)*(SessionDB!$C$2:$C$64<$A12)*(SessionDB!$D$2:$D$64>$A12)*((SessionDB!$I$2:$I$64=$E$3)+(SessionDB!$I$2:$I$64="all")),0)),""))
A13: 12:30 | I13: =IFERROR(INDEX(SessionDB!$H$2:$H$64,MATCH(1,(SessionDB!$B$2:$B$64=5)*(SessionDB!$C$2:$C$64=$A13)*((SessionDB!$I$2:$I$64=$E$3)+(SessionDB!$I$2:$I$64="all")),0)),IFERROR(INDEX(SessionDB!$H$2:$H$64,MATCH(1,(SessionDB!$B$2:$B$64=5)*(SessionDB!$C$2:$C$64<$A13)*(SessionDB!$D$2:$D$64>$A13)*((SessionDB!$I$2:$I$64=$E$3)+(SessionDB!$I$2:$I$64="all")),0)),""))
A14: 13:00 | B14: Closing Keynote & Awards Lead: Dr. Sarah Chen • Main Hall | I14: =IFERROR(INDEX(SessionDB!$H$2:$H$64,MATCH(1,(SessionDB!$B$2:$B$64=5)*(SessionDB!$C$2:$C$64=$A14)*((SessionDB!$I$2:$I$64=$E$3)+(SessionDB!$I$2:$I$64="all")),0)),IFERROR(INDEX(SessionDB!$H$2:$H$64,MATCH(1,(SessionDB!$B$2:$B$64=5)*(SessionDB!$C$2:$C$64<$A14)*(SessionDB!$D$2:$D$64>$A14)*((SessionDB!$I$2:$I$64=$E$3)+(SessionDB!$I$2:$I$64="all")),0)),""))
A15: 13:30 | I15: =IFERROR(INDEX(SessionDB!$H$2:$H$64,MATCH(1,(SessionDB!$B$2:$B$64=5)*(SessionDB!$C$2:$C$64=$A15)*((SessionDB!$I$2:$I$64=$E$3)+(SessionDB!$I$2:$I$64="all")),0)),IFERROR(INDEX(SessionDB!$H$2:$H$64,MATCH(1,(SessionDB!$B$2:$B$64=5)*(SessionDB!$C$2:$C$64<$A15)*(SessionDB!$D$2:$D$64>$A15)*((SessionDB!$I$2:$I$64=$E$3)+(SessionDB!$I$2:$I$64="all")),0)),""))
A16: 14:00 | I16: =IFERROR(INDEX(SessionDB!$H$2:$H$64,MATCH(1,(SessionDB!$B$2:$B$64=5)*(SessionDB!$C$2:$C$64=$A16)*((SessionDB!$I$2:$I$64=$E$3)+(SessionDB!$I$2:$I$64="all")),0)),IFERROR(INDEX(SessionDB!$H$2:$H$64,MATCH(1,(SessionDB!$B$2:$B$64=5)*(SessionDB!$C$2:$C$64<$A16)*(SessionDB!$D$2:$D$64>$A16)*((SessionDB!$I$2:$I$64=$E$3)+(SessionDB!$I$2:$I$64="all")),0)),""))
A17: 14:30 | I17: =IFERROR(INDEX(SessionDB!$H$2:$H$64,MATCH(1,(SessionDB!$B$2:$B$64=5)*(SessionDB!$C$2:$C$64=$A17)*((SessionDB!$I$2:$I$64=$E$3)+(SessionDB!$I$2:$I$64="all")),0)),IFERROR(INDEX(SessionDB!$H$2:$H$64,MATCH(1,(SessionDB!$B$2:$B$64=5)*(SessionDB!$C$2:$C$64<$A17)*(SessionDB!$D$2:$D$64>$A17)*((SessionDB!$I$2:$I$64=$E$3)+(SessionDB!$I$2:$I$64="all")),0)),""))
