Workbook

Sheet SessionDB
A1: ID | B1: Day | C1: Start | D1: End | E1: Title | F1: Lead | G1: Room | H1: Type | I1: Track | J1: Capacity | K1: Expected Participants | R1: Tracks (auto) | S1: Room Check
A2: 1 | B2: 1 | C2: 09:00 | D2: 10:00 | E2: Opening Keynote | F2: Dr. Sarah Chen | G2: Main Hall | H2: Keynote | I2: all | J2: 200 | K2: 140 | R2: =sort(unique(filter(I2:I200,LOWER(I2:I200)<>"all"))) | S2: =IF(OR(G2="",B2="",C2=""),"",IF(SUMPRODUCT(('Room Management'!$A$4:$A$103="D"&B2)*('Room Management'!$B$4:$B$103=C2)*(INDEX('Room Management'!$C$4:$M$103,0,MATCH(G2,'Room Management'!$C$2:$M$2,0))<>""))>0,"OK","CONFLICT"))
A3: 2 | B3: 1 | C3: 10:30 | D3: 12:00 | E3: Leading Through Change | F3: Mark Torres | G3: Room A1 | H3: Leadership | I3: Leadership | J3: 40 | K3: 28 | S3: =IF(OR(G3="",B3="",C3=""),"",IF(SUMPRODUCT(('Room Management'!$A$4:$A$103="D"&B3)*('Room Management'!$B$4:$B$103=C3)*(INDEX('Room Management'!$C$4:$M$103,0,MATCH(G3,'Room Management'!$C$2:$M$2,0))<>""))>0,"OK","CONFLICT"))
A4: 3 | B4: 1 | C4: 10:30 | D4: 12:00 | E4: API Design Patterns | F4: Priya Sharma | G4: Room B1 | H4: Technical | I4: Technical | J4: 45 | K4: 31 | S4: =IF(OR(G4="",B4="",C4=""),"",IF(SUMPRODUCT(('Room Management'!$A$4:$A$103="D"&B4)*('Room Management'!$B$4:$B$103=C4)*(INDEX('Room Management'!$C$4:$M$103,0,MATCH(G4,'Room Management'!$C$2:$M$2,0))<>""))>0,"OK","CONFLICT"))
A5: 4 | B5: 1 | C5: 10:30 | D5: 12:00 | E5: Empathy Mapping 101 | F5: Lena Müller | G5: Room C1 | H5: Design Thinking | I5: Design Thinking | J5: 35 | K5: 24 | S5: =IF(OR(G5="",B5="",C5=""),"",IF(SUMPRODUCT(('Room Management'!$A$4:$A$103="D"&B5)*('Room Management'!$B$4:$B$103=C5)*(INDEX('Room Management'!$C$4:$M$103,0,MATCH(G5,'Room Management'!$C$2:$M$2,0))<>""))>0,"OK","CONFLICT"))
A6: 5 | B6: 1 | C6: 10:30 | D6: 12:00 | E6: Lean Process Improvement | F6: James Wright | G6: Room D1 | H6: Operations | I6: Operations | J6: 30 | K6: 21 | S6: =IF(OR(G6="",B6="",C6=""),"",IF(SUMPRODUCT(('Room Management'!$A$4:$A$103="D"&B6)*('Room Management'!$B$4:$B$103=C6)*(INDEX('Room Management'!$C$4:$M$103,0,MATCH(G6,'Room Management'!$C$2:$M$2,0))<>""))>0,"OK","CONFLICT"))
A7: 6 | B7: 1 | C7: 12:00 | D7: 13:00 | E7: Lunch & Networking | G7: Atrium | H7: Break | I7: all | J7: 200 | K7: 200 | S7: =IF(OR(G7="",B7="",C7=""),"",IF(SUMPRODUCT(('Room Management'!$A$4:$A$103="D"&B7)*('Room Management'!$B$4:$B$103=C7)*(INDEX('Room Management'!$C$4:$M$103,0,MATCH(G7,'Room Management'!$C$2:$M$2,0))<>""))>0,"OK","CONFLICT"))
A8: 7 | B8: 1 | C8: 13:00 | D8: 14:30 | E8: Stakeholder Alignment | F8: Aisha Johnson | G8: Room A1 | H8: Leadership | I8: Leadership | J8: 40 | K8: 28 | S8: =IF(OR(G8="",B8="",C8=""),"",IF(SUMPRODUCT(('Room Management'!$A$4:$A$103="D"&B8)*('Room Management'!$B$4:$B$103=C8)*(INDEX('Room Management'!$C$4:$M$103,0,MATCH(G8,'Room Management'!$C$2:$M$2,0))<>""))>0,"OK","CONFLICT"))
A9: 8 | B9: 1 | C9: 13:00 | D9: 14:30 | E9: Cloud Infrastructure | F9: David Kim | G9: Room B1 | H9: Technical | I9: Technical | J9: 50 | K9: 35 | S9: =IF(OR(G9="",B9="",C9=""),"",IF(SUMPRODUCT(('Room Management'!$A$4:$A$103="D"&B9)*('Room Management'!$B$4:$B$103=C9)*(INDEX('Room Management'!$C$4:$M$103,0,MATCH(G9,'Room Management'!$C$2:$M$2,0))<>""))>0,"OK","CONFLICT"))
A10: 9 | B10: 1 | C10: 13:00 | D10: 14:30 | E10: Prototyping Sprint | F10: Carlos Ruiz | G10: Room C1 | H10: Design Thinking | I10: Design Thinking | J10: 35 | K10: 24 | S10: =IF(OR(G10="",B10="",C10=""),"",IF(SUMPRODUCT(('Room Management'!$A$4:$A$103="D"&B10)*('Room Management'!$B$4:$B$103=C10)*(INDEX('Room Management'!$C$4:$M$103,0,MATCH(G10,'Room Management'!$C$2:$M$2,0))<>""))>0,"OK","CONFLICT"))
A11: 10 | B11: 1 | C11: 13:00 | D11: 14:30 | E11: Risk Assessment | F11: Nina Petrov | G11: Room D1 | H11: Operations | I11: Operations | J11: 30 | K11: 21 | S11: =IF(OR(G11="",B11="",C11=""),"",IF(SUMPRODUCT(('Room Management'!$A$4:$A$103="D"&B11)*('Room Management'!$B$4:$B$103=C11)*(INDEX('Room Management'!$C$4:$M$103,0,MATCH(G11,'Room Management'!$C$2:$M$2,0))<>""))>0,"OK","CONFLICT"))
A12: 11 | B12: 1 | C12: 14:30 | D12: 15:00 | E12: Afternoon Break | G12: Atrium | H12: Break | I12: all | J12: 200 | K12: 200 | S12: =IF(OR(G12="",B12="",C12=""),"",IF(SUMPRODUCT(('Room Management'!$A$4:$A$103="D"&B12)*('Room Management'!$B$4:$B$103=C12)*(INDEX('Room Management'!$C$4:$M$103,0,MATCH(G12,'Room Management'!$C$2:$M$2,0))<>""))>0,"OK","CONFLICT"))
A13: 12 | B13: 1 | C13: 15:00 | D13: 16:30 | E13: Feedback Culture | F13: Tom Bradley | G13: Room A1 | H13: Leadership | I13: Leadership | J13: 38 | K13: 26 | S13: =IF(OR(G13="",B13="",C13=""),"",IF(SUMPRODUCT(('Room Management'!$A$4:$A$103="D"&B13)*('Room Management'!$B$4:$B$103=C13)*(INDEX('Room Management'!$C$4:$M$103,0,MATCH(G13,'Room Management'!$C$2:$M$2,0))<>""))>0,"OK","CONFLICT"))
A14: 13 | B14: 1 | C14: 15:00 | D14: 16:30 | E14: Data Pipeline Design | F14: Wei Zhang | G14: Room B1 | H14: Technical | I14: Technical | J14: 42 | K14: 29 | S14: =IF(OR(G14="",B14="",C14=""),"",IF(SUMPRODUCT(('Room Management'!$A$4:$A$103="D"&B14)*('Room Management'!$B$4:$B$103=C14)*(INDEX('Room Management'!$C$4:$M$103,0,MATCH(G14,'Room Management'!$C$2:$M$2,0))<>""))>0,"OK","CONFLICT"))
A15: 14 | B15: 1 | C15: 15:00 | D15: 16:30 | E15: Service Blueprinting | F15: Lena Müller | G15: Room C1 | H15: Design Thinking | I15: Design Thinking | J15: 32 | K15: 22 | S15: =IF(OR(G15="",B15="",C15=""),"",IF(SUMPRODUCT(('Room Management'!$A$4:$A$103="D"&B15)*('Room Management'!$B$4:$B$103=C15)*(INDEX('Room Management'!$C$4:$M$103,0,MATCH(G15,'Room Management'!$C$2:$M$2,0))<>""))>0,"OK","CONFLICT"))
A16: 15 | B16: 1 | C16: 15:00 | D16: 16:30 | E16: Agile Ceremonies | F16: Rachel Green | G16: Room D1 | H16: Operations | I16: Operations | J16: 28 | K16: 19 | S16: =IF(OR(G16="",B16="",C16=""),"",IF(SUMPRODUCT(('Room Management'!$A$4:$A$103="D"&B16)*('Room Management'!$B$4:$B$103=C16)*(INDEX('Room Management'!$C$4:$M$103,0,MATCH(G16,'Room Management'!$C$2:$M$2,0))<>""))>0,"OK","CONFLICT"))
A17: 16 | B17: 2 | C17: 09:00 | D17: 10:30 | E17: Emotional Intelligence | F17: Aisha Johnson | G17: Room A1 | H17: Leadership | I17: Leadership | J17: 40 | K17: 28 | S17: =IF(OR(G17="",B17="",C17=""),"",IF(SUMPRODUCT(('Room Management'!$A$4:$A$103="D"&B17)*('Room Management'!$B$4:$B$103=C17)*(INDEX('Room Management'!$C$4:$M$103,0,MATCH(G17,'Room Management'!$C$2:$M$2,0))<>""))>0,"OK","CONFLICT"))
A18: 17 | B18: 2 | C18: 09:00 | D18: 10:30 | E18: Security Fundamentals | F18: Alex Novak | G18: Room B1 | H18: Technical | I18: Technical | J18: 48 | K18: 33 | S18: =IF(OR(G18="",B18="",C18=""),"",IF(SUMPRODUCT(('Room Management'!$A$4:$A$103="D"&B18)*('Room Management'!$B$4:$B$103=C18)*(INDEX('Room Management'!$C$4:$M$103,0,MATCH(G18,'Room Management'!$C$2:$M$2,0))<>""))>0,"OK","CONFLICT"))
A19: 18 | B19: 2 | C19: 09:00 | D19: 10:30 | E19: Design Systems | F19: Yuki Tanaka | G19: Room C1 | H19: Design Thinking | I19: Design Thinking | J19: 35 | K19: 24 | S19: =IF(OR(G19="",B19="",C19=""),"",IF(SUMPRODUCT(('Room Management'!$A$4:$A$103="D"&B19)*('Room Management'!$B$4:$B$103=C19)*(INDEX('Room Management'!$C$4:$M$103,0,MATCH(G19,'Room Management'!$C$2:$M$2,0))<>""))>0,"OK","CONFLICT"))
A20: 19 | B20: 2 | C20: 09:00 | D20: 10:30 | E20: Capacity Planning | F20: James Wright | G20: Room D1 | H20: Operations | I20: Operations | J20: 30 | K20: 21 | S20: =IF(OR(G20="",B20="",C20=""),"",IF(SUMPRODUCT(('Room Management'!$A$4:$A$103="D"&B20)*('Room Management'!$B$4:$B$103=C20)*(INDEX('Room Management'!$C$4:$M$103,0,MATCH(G20,'Room Management'!$C$2:$M$2,0))<>""))>0,"OK","CONFLICT"))
A21: 20 | B21: 2 | C21: 10:30 | D21: 11:00 | E21: Morning Break | G21: Atrium | H21: Break | I21: all | J21: 200 | K21: 200 | S21: =IF(OR(G21="",B21="",C21=""),"",IF(SUMPRODUCT(('Room Management'!$A$4:$A$103="D"&B21)*('Room Management'!$B$4:$B$103=C21)*(INDEX('Room Management'!$C$4:$M$103,0,MATCH(G21,'Room Management'!$C$2:$M$2,0))<>""))>0,"OK","CONFLICT"))
A22: 21 | B22: 2 | C22: 11:00 | D22: 12:00 | E22: Panel: Future of Work | F22: Multiple Speakers | G22: Main Hall | H22: Keynote | I22: all | J22: 180 | K22: 125 | S22: =IF(OR(G22="",B22="",C22=""),"",IF(SUMPRODUCT(('Room Management'!$A$4:$A$103="D"&B22)*('Room Management'!$B$4:$B$103=C22)*(INDEX('Room Management'!$C$4:$M$103,0,MATCH(G22,'Room Management'!$C$2:$M$2,0))<>""))>0,"OK","CONFLICT"))
A23: 22 | B23: 2 | C23: 12:00 | D23: 13:00 | E23: Lunch & Networking | G23: Atrium | H23: Break | I23: all | J23: 200 | K23: 200 | S23: =IF(OR(G23="",B23="",C23=""),"",IF(SUMPRODUCT(('Room Management'!$A$4:$A$103="D"&B23)*('Room Management'!$B$4:$B$103=C23)*(INDEX('Room Management'!$C$4:$M$103,0,MATCH(G23,'Room Management'!$C$2:$M$2,0))<>""))>0,"OK","CONFLICT"))
A24: 23 | B24: 2 | C24: 13:00 | D24: 14:30 | E24: Conflict Resolution | F24: Mark Torres | G24: Room A1 | H24: Leadership | I24: Leadership | J24: 40 | K24: 28 | S24: =IF(OR(G24="",B24="",C24=""),"",IF(SUMPRODUCT(('Room Management'!$A$4:$A$103="D"&B24)*('Room Management'!$B$4:$B$103=C24)*(INDEX('Room Management'!$C$4:$M$103,0,MATCH(G24,'Room Management'!$C$2:$M$2,0))<>""))>0,"OK","CONFLICT"))
A25: 24 | B25: 2 | C25: 13:00 | D25: 14:30 | E25: DevOps Practices | F25: Priya Sharma | G25: Room B1 | H25: Technical | I25: Technical | J25: 50 | K25: 35 | S25: =IF(OR(G25="",B25="",C25=""),"",IF(SUMPRODUCT(('Room Management'!$A$4:$A$103="D"&B25)*('Room Management'!$B$4:$B$103=C25)*(INDEX('Room Management'!$C$4:$M$103,0,MATCH(G25,'Room Management'!$C$2:$M$2,0))<>""))>0,"OK","CONFLICT"))
A26: 25 | B26: 2 | C26: 13:00 | D26: 14:30 | E26: Accessibility Workshop | F26: Carlos Ruiz | G26: Room C1 | H26: Design Thinking | I26: Design Thinking | J26: 36 | K26: 25 | S26: =IF(OR(G26="",B26="",C26=""),"",IF(SUMPRODUCT(('Room Management'!$A$4:$A$103="D"&B26)*('Room Management'!$B$4:$B$103=C26)*(INDEX('Room Management'!$C$4:$M$103,0,MATCH(G26,'Room Management'!$C$2:$M$2,0))<>""))>0,"OK","CONFLICT"))
A27: 26 | B27: 2 | C27: 13:00 | D27: 14:30 | E27: Vendor Management | F27: Nina Petrov | G27: Room D1 | H27: Operations | I27: Operations | J27: 28 | K27: 19 | S27: =IF(OR(G27="",B27="",C27=""),"",IF(SUMPRODUCT(('Room Management'!$A$4:$A$103="D"&B27)*('Room Management'!$B$4:$B$103=C27)*(INDEX('Room Management'!$C$4:$M$103,0,MATCH(G27,'Room Management'!$C$2:$M$2,0))<>""))>0,"OK","CONFLICT"))
A28: 27 | B28: 2 | C28: 14:30 | D28: 15:00 | E28: Afternoon Break | G28: Atrium | H28: Break | I28: all | J28: 200 | K28: 200 | S28: =IF(OR(G28="",B28="",C28=""),"",IF(SUMPRODUCT(('Room Management'!$A$4:$A$103="D"&B28)*('Room Management'!$B$4:$B$103=C28)*(INDEX('Room Management'!$C$4:$M$103,0,MATCH(G28,'Room Management'!$C$2:$M$2,0))<>""))>0,"OK","CONFLICT"))
A29: 28 | B29: 2 | C29: 15:00 | D29: 16:30 | E29: Strategic Planning | F29: Tom Bradley | G29: Room A1 | H29: Leadership | I29: Leadership | J29: 42 | K29: 29 | S29: =IF(OR(G29="",B29="",C29=""),"",IF(SUMPRODUCT(('Room Management'!$A$4:$A$103="D"&B29)*('Room Management'!$B$4:$B$103=C29)*(INDEX('Room Management'!$C$4:$M$103,0,MATCH(G29,'Room Management'!$C$2:$M$2,0))<>""))>0,"OK","CONFLICT"))
A30: 29 | B30: 2 | C30: 15:00 | D30: 16:30 | E30: Performance Testing | F30: David Kim | G30: Room B1 | H30: Technical | I30: Technical | J30: 44 | K30: 30 | S30: =IF(OR(G30="",B30="",C30=""),"",IF(SUMPRODUCT(('Room Management'!$A$4:$A$103="D"&B30)*('Room Management'!$B$4:$B$103=C30)*(INDEX('Room Management'!$C$4:$M$103,0,MATCH(G30,'Room Management'!$C$2:$M$2,0))<>""))>0,"OK","CONFLICT"))
A31: 30 | B31: 2 | C31: 15:00 | D31: 16:30 | E31: User Research Methods | F31: Yuki Tanaka | G31: Room C1 | H31: Design Thinking | I31: Design Thinking | J31: 34 | K31: 23 | S31: =IF(OR(G31="",B31="",C31=""),"",IF(SUMPRODUCT(('Room Management'!$A$4:$A$103="D"&B31)*('Room Management'!$B$4:$B$103=C31)*(INDEX('Room Management'!$C$4:$M$103,0,MATCH(G31,'Room Management'!$C$2:$M$2,0))<>""))>0,"OK","CONFLICT"))
A32: 31 | B32: 2 | C32: 15:00 | D32: 16:30 | E32: Budget Forecasting | F32: Rachel Green | G32: Room D1 | H32: Operations | I32: Operations | J32: 26 | K32: 18 | S32: =IF(OR(G32="",B32="",C32=""),"",IF(SUMPRODUCT(('Room Management'!$A$4:$A$103="D"&B32)*('Room Management'!$B$4:$B$103=C32)*(INDEX('Room Management'!$C$4:$M$103,0,MATCH(G32,'Room Management'!$C$2:$M$2,0))<>""))>0,"OK","CONFLICT"))
A33: 32 | B33: 3 | C33: 09:00 | D33: 10:00 | E33: Midweek Keynote | F33: Dr. Sarah Chen | G33: Main Hall | H33: Keynote | I33: all | J33: 190 | K33: 133 | S33: =IF(OR(G33="",B33="",C33=""),"",IF(SUMPRODUCT(('Room Management'!$A$4:$A$103="D"&B33)*('Room Management'!$B$4:$B$103=C33)*(INDEX('Room Management'!$C$4:$M$103,0,MATCH(G33,'Room Management'!$C$2:$M$2,0))<>""))>0,"OK","CONFLICT"))
A34: 33 | B34: 3 | C34: 10:00 | D34: 10:30 | E34: Morning Break | G34: Atrium | H34: Break | I34: all | J34: 200 | K34: 200 | S34: =IF(OR(G34="",B34="",C34=""),"",IF(SUMPRODUCT(('Room Management'!$A$4:$A$103="D"&B34)*('Room Management'!$B$4:$B$103=C34)*(INDEX('Room Management'!$C$4:$M$103,0,MATCH(G34,'Room Management'!$C$2:$M$2,0))<>""))>0,"OK","CONFLICT"))
A35: 34 | B35: 3 | C35: 10:30 | D35: 12:00 | E35: Cross-Team Collaboration | F35: Aisha Johnson | G35: Room A1 | H35: Leadership | I35: Leadership | J35: 40 | K35: 28 | S35: =IF(OR(G35="",B35="",C35=""),"",IF(SUMPRODUCT(('Room Management'!$A$4:$A$103="D"&B35)*('Room Management'!$B$4:$B$103=C35)*(INDEX('Room Management'!$C$4:$M$103,0,MATCH(G35,'Room Management'!$C$2:$M$2,0))<>""))>0,"OK","CONFLICT"))
A36: 35 | B36: 3 | C36: 10:30 | D36: 12:00 | E36: AI/ML Integration | F36: Wei Zhang | G36: Room B1 | H36: Technical | I36: Technical | J36: 52 | K36: 36 | S36: =IF(OR(G36="",B36="",C36=""),"",IF(SUMPRODUCT(('Room Management'!$A$4:$A$103="D"&B36)*('Room Management'!$B$4:$B$103=C36)*(INDEX('Room Management'!$C$4:$M$103,0,MATCH(G36,'Room Management'!$C$2:$M$2,0))<>""))>0,"OK","CONFLICT"))
A37: 36 | B37: 3 | C37: 10:30 | D37: 12:00 | E37: Workshop Facilitation | F37: Lena Müller | G37: Room C1 | H37: Design Thinking | I37: Design Thinking | J37: 34 | K37: 23 | S37: =IF(OR(G37="",B37="",C37=""),"",IF(SUMPRODUCT(('Room Management'!$A$4:$A$103="D"&B37)*('Room Management'!$B$4:$B$103=C37)*(INDEX('Room Management'!$C$4:$M$103,0,MATCH(G37,'Room Management'!$C$2:$M$2,0))<>""))>0,"OK","CONFLICT"))
A38: 37 | B38: 3 | C38: 10:30 | D38: 12:00 | E38: Incident Response | F38: Alex Novak | G38: Room D1 | H38: Operations | I38: Operations | J38: 30 | K38: 21 | S38: =IF(OR(G38="",B38="",C38=""),"",IF(SUMPRODUCT(('Room Management'!$A$4:$A$103="D"&B38)*('Room Management'!$B$4:$B$103=C38)*(INDEX('Room Management'!$C$4:$M$103,0,MATCH(G38,'Room Management'!$C$2:$M$2,0))<>""))>0,"OK","CONFLICT"))
A39: 38 | B39: 3 | C39: 12:00 | D39: 13:00 | E39: Lunch & Networking | G39: Atrium | H39: Break | I39: all | J39: 200 | K39: 200 | S39: =IF(OR(G39="",B39="",C39=""),"",IF(SUMPRODUCT(('Room Management'!$A$4:$A$103="D"&B39)*('Room Management'!$B$4:$B$103=C39)*(INDEX('Room Management'!$C$4:$M$103,0,MATCH(G39,'Room Management'!$C$2:$M$2,0))<>""))>0,"OK","CONFLICT"))
A40: 39 | B40: 3 | C40: 13:00 | D40: 16:30 | E40: Cross-Track Hackathon | F40: All Facilitators | G40: All Rooms | H40: Keynote | I40: all | J40: 200 | K40: 140 | S40: =IF(OR(G40="",B40="",C40=""),"",IF(SUMPRODUCT(('Room Management'!$A$4:$A$103="D"&B40)*('Room Management'!$B$4:$B$103=C40)*(INDEX('Room Management'!$C$4:$M$103,0,MATCH(G40,'Room Management'!$C$2:$M$2,0))<>""))>0,"OK","CONFLICT"))
...

Sheet ParticipantsDB
A1: ID | B1: Username | C1: Email | D1: Department | E1: Job Title | F1: Primary Track | G1: Non-Local | H1: Hotel | I1: Day 1 | J1: Day 2 | K1: Day 3 | L1: Day 4 | M1: Day 5 | N1: Emergency Contact | O1: Emergency Phone | P1: Notes
A2: P001 | B2: alice.martinez | C2: alice.martinez@acme.com | D2: Product | E2: Product Manager | F2: Leadership | G2: Local | I2: Yes | J2: Yes | K2: Yes | L2: Yes | M2: Yes | N2: John Martinez | O2: +1-555-0101
A3: P002 | B3: ben.okafor | C3: ben.okafor@techstart.io | D3: Engineering | E3: Senior Developer | F3: Technical | G3: Non-Local | H3: Hilton Downtown | I3: Yes | J3: Yes | K3: Yes | L3: Yes | M3: No | N3: Mary Okafor | O3: +1-555-0102
A4: P003 | B4: clara.johansson | C4: clara.j@nordicdesign.se | D4: Design | E4: UX Lead | F4: Design Thinking | G4: Non-Local | H4: Marriott Convention | I4: Yes | J4: Yes | K4: Yes | L4: Yes | M4: Yes | N4: Erik Johansson | O4: +46-70-555-0103
A5: P004 | B5: daniel.park | C5: d.park@globalops.com | D5: Operations | E5: Ops Director | F5: Operations | G5: Local | I5: Yes | J5: No | K5: Yes | L5: Yes | M5: Yes | N5: Soo-Min Park | O5: +1-555-0104
A6: P005 | B6: elena.rossi | C6: e.rossi@finserv.it | D6: Strategy | E6: Team Lead | F6: Leadership | G6: Non-Local | H6: Hyatt Regency | I6: Yes | J6: Yes | K6: No | L6: Yes | M6: Yes | N6: Marco Rossi | O6: +39-555-0105
A7: P006 | B7: fatima.alhassan | C7: f.alhassan@govtech.ae | D7: Engineering | E7: Systems Architect | F7: Technical | G7: Non-Local | H7: Hilton Downtown | I7: Yes | J7: Yes | K7: Yes | L7: Yes | M7: Yes | N7: Ahmed Al-Hassan | O7: +971-55-0106
A8: P007 | B8: george.chen | C8: g.chen@startuplab.cn | D8: Design | E8: Design Director | F8: Design Thinking | G8: Non-Local | H8: Marriott Convention | I8: Yes | J8: Yes | K8: Yes | L8: No | M8: Yes | N8: Wei Chen | O8: +86-138-0107
A9: P008 | B9: hannah.weber | C9: h.weber@logicorp.de | D9: Operations | E9: Process Engineer | F9: Operations | G9: Non-Local | H9: Holiday Inn Express | I9: Yes | J9: Yes | K9: Yes | L9: Yes | M9: Yes | N9: Thomas Weber | O9: +49-170-0108
A10: P009 | B10: ibrahim.diallo | C10: i.diallo@afrotech.sn | D10: Engineering | E10: Eng. Manager | F10: Technical | G10: Non-Local | H10: Hyatt Regency | I10: No | J10: Yes | K10: Yes | L10: Yes | M10: Yes | N10: Aminata Diallo | O10: +221-77-0109
A11: P010 | B11: julia.fernandez | C11: j.fernandez@consulta.mx | D11: Strategy | E11: Strategy Consultant | F11: Leadership | G11: Non-Local | H11: Hilton Downtown | I11: Yes | J11: Yes | K11: Yes | L11: Yes | M11: Yes | N11: Roberto Fernandez | O11: +52-55-0110
A12: P011 | B12: kevin.obrien | C12: k.obrien@dublinsoft.ie | D12: Engineering | E12: DevOps Lead | F12: Technical | G12: Non-Local | H12: Marriott Convention | I12: Yes | J12: Yes | K12: Yes | L12: Yes | M12: No | N12: Siobhan O'Brien | O12: +353-86-0111
A13: P012 | B13: lina.nakamura | C13: l.nakamura@tokyoux.jp | D13: Design | E13: Service Designer | F13: Design Thinking | G13: Non-Local | H13: Holiday Inn Express | I13: Yes | J13: No | K13: Yes | L13: Yes | M13: Yes | N13: Yuki Nakamura | O13: +81-90-0112
A14: P013 | B14: marcus.brown | C14: m.brown@opscenter.us | D14: Logistics | E14: Logistics Mgr | F14: Operations | G14: Local | I14: Yes | J14: Yes | K14: Yes | L14: Yes | M14: Yes | N14: Sarah Brown | O14: +1-555-0113
A15: P014 | B15: nadia.kovalenko | C15: n.kovalenko@dataflow.ua | D15: Data | E15: Data Engineer | F15: Technical | G15: Non-Local | H15: Hyatt Regency | I15: Yes | J15: Yes | K15: Yes | L15: Yes | M15: Yes | N15: Oleksandr K. | O15: +380-67-0114
A16: P015 | B16: oscar.lindgren | C16: o.lindgren@greentech.se | D16: Sustainability | E16: Sustainability Lead | F16: Operations | G16: Non-Local | H16: Marriott Convention | I16: Yes | J16: Yes | K16: No | L16: Yes | M16: Yes | N16: Anna Lindgren | O16: +46-73-0115
A17: P016 | B17: priya.menon | C17: p.menon@cloudnine.in | D17: Engineering | E17: VP Engineering | F17: Technical | G17: Non-Local | H17: Hilton Downtown | I17: Yes | J17: Yes | K17: Yes | L17: Yes | M17: Yes | N17: Raj Menon | O17: +91-98-0116
A18: P017 | B18: quentin.dubois | C18: q.dubois@parislab.fr | D18: Innovation | E18: Innovation Lead | F18: Design Thinking | G18: Non-Local | H18: Holiday Inn Express | I18: Yes | J18: Yes | K18: Yes | L18: Yes | M18: No | N18: Marie Dubois | O18: +33-6-0117
A19: P018 | B19: rachel.kim | C19: r.kim@seoultech.kr | D19: Operations | E19: Project Manager | F19: Operations | G19: Non-Local | H19: Hilton Downtown | I19: Yes | J19: Yes | K19: Yes | L19: Yes | M19: Yes | N19: Jun Kim | O19: +82-10-0118
A20: P019 | B20: sam.adeyemi | C20: s.adeyemi@lagosops.ng | D20: Executive | E20: COO | F20: Leadership | G20: Non-Local | H20: Hyatt Regency | I20: Yes | J20: Yes | K20: Yes | L20: No | M20: Yes | N20: Grace Adeyemi | O20: +234-80-0119
A21: P020 | B21: tara.singh | C21: t.singh@quantumleap.ca | D21: Engineering | E21: CTO | F21: Technical | G21: Local | I21: Yes | J21: Yes | K21: Yes | L21: Yes | M21: Yes | N21: Arjun Singh | O21: +1-604-0120

Sheet Participants Statistics
A1: PARTICIPANTS STATISTICS | G1: HotelList | H1: DeptList
G2: =sort(unique(filter(ParticipantsDB!H2:H200,(ParticipantsDB!H2:H200<>"")*(LEN(ParticipantsDB!H2:H200)>0)))) | H2: =sort(unique(filter(ParticipantsDB!D2:D200,(ParticipantsDB!D2:D200<>"")*(LEN(ParticipantsDB!D2:D200)>0))))
A3: TOTAL OVERVIEW | D3: HOTEL BREAKDOWN
A4: Total Participants | B4: =COUNTA(ParticipantsDB!A2:A200) | D4: =IFERROR(INDEX($G$2:$G$50,1),"") | E4: =IF(D4="","",COUNTIF(ParticipantsDB!H2:H200,D4))
A5: Local Participants | B5: =COUNTIF(ParticipantsDB!G2:G200,"Local") | D5: =IFERROR(INDEX($G$2:$G$50,2),"") | E5: =IF(D5="","",COUNTIF(ParticipantsDB!H2:H200,D5))
A6: Non-Local Participants | B6: =COUNTIF(ParticipantsDB!G2:G200,"Non-Local") | D6: =IFERROR(INDEX($G$2:$G$50,3),"") | E6: =IF(D6="","",COUNTIF(ParticipantsDB!H2:H200,D6))
A7: Non-Local % | B7: =IFERROR(COUNTIF(ParticipantsDB!G2:G200,"Non-Local")/COUNTA(ParticipantsDB!A2:A200),0) | D7: =IFERROR(INDEX($G$2:$G$50,4),"") | E7: =IF(D7="","",COUNTIF(ParticipantsDB!H2:H200,D7))
D8: =IFERROR(INDEX($G$2:$G$50,5),"") | E8: =IF(D8="","",COUNTIF(ParticipantsDB!H2:H200,D8))
A9: DAILY ATTENDANCE | D9: =IFERROR(INDEX($G$2:$G$50,6),"") | E9: =IF(D9="","",COUNTIF(ParticipantsDB!H2:H200,D9))
A10: Day 1 — Mon Mar 9 | B10: =COUNTIF(ParticipantsDB!I2:I200,"Yes") | D10: =IFERROR(INDEX($G$2:$G$50,7),"") | E10: =IF(D10="","",COUNTIF(ParticipantsDB!H2:H200,D10))
A11: Day 2 — Tue Mar 10 | B11: =COUNTIF(ParticipantsDB!J2:J200,"Yes") | D11: =IFERROR(INDEX($G$2:$G$50,8),"") | E11: =IF(D11="","",COUNTIF(ParticipantsDB!H2:H200,D11))
A12: Day 3 — Wed Mar 11 | B12: =COUNTIF(ParticipantsDB!K2:K200,"Yes") | D12: =IFERROR(INDEX($G$2:$G$50,9),"") | E12: =IF(D12="","",COUNTIF(ParticipantsDB!H2:H200,D12))
A13: Day 4 — Thu Mar 12 | B13: =COUNTIF(ParticipantsDB!L2:L200,"Yes") | D13: =IFERROR(INDEX($G$2:$G$50,10),"") | E13: =IF(D13="","",COUNTIF(ParticipantsDB!H2:H200,D13))
A14: Day 5 — Fri Mar 13 | B14: =COUNTIF(ParticipantsDB!M2:M200,"Yes") | D14: No Hotel Assigned | E14: =COUNTIFS(ParticipantsDB!G2:G200,"Non-Local",ParticipantsDB!H2:H200,"")
A15: Highest Day | B15: =MAX(B10:B14) | D15: Total Non-Local (verify) | E15: =COUNTIF(ParticipantsDB!G2:G200,"Non-Local")
A16: Lowest Day | B16: =MIN(B10:B14)
A17: Avg Daily Attendance | B17: =IFERROR(AVERAGE(B10:B14),0) | D17: TRACK × LOCALITY
D18: =IF(IFERROR(INDEX(SessionDB!$R$2:$R$50,1),"")="","",IFERROR(INDEX(SessionDB!$R$2:$R$50,1),"")&" — Local") | E18: =IF(D18="","",COUNTIFS(ParticipantsDB!F2:F200,IFERROR(INDEX(SessionDB!$R$2:$R$50,1),""),ParticipantsDB!G2:G200,"Local"))
A19: BREAKDOWN BY TRACK | D19: =IF(IFERROR(INDEX(SessionDB!$R$2:$R$50,1),"")="","",IFERROR(INDEX(SessionDB!$R$2:$R$50,1),"")&" — Non-Local") | E19: =IF(D19="","",COUNTIFS(ParticipantsDB!F2:F200,IFERROR(INDEX(SessionDB!$R$2:$R$50,1),""),ParticipantsDB!G2:G200,"Non-Local"))
A20: =IFERROR(INDEX(SessionDB!$R$2:$R$50,1),"") | B20: =IF(A20="","",COUNTIF(ParticipantsDB!F2:F200,A20)) | D20: =IF(IFERROR(INDEX(SessionDB!$R$2:$R$50,2),"")="","",IFERROR(INDEX(SessionDB!$R$2:$R$50,2),"")&" — Local") | E20: =IF(D20="","",COUNTIFS(ParticipantsDB!F2:F200,IFERROR(INDEX(SessionDB!$R$2:$R$50,2),""),ParticipantsDB!G2:G200,"Local"))
A21: =IFERROR(INDEX(SessionDB!$R$2:$R$50,2),"") | B21: =IF(A21="","",COUNTIF(ParticipantsDB!F2:F200,A21)) | D21: =IF(IFERROR(INDEX(SessionDB!$R$2:$R$50,2),"")="","",IFERROR(INDEX(SessionDB!$R$2:$R$50,2),"")&" — Non-Local") | E21: =IF(D21="","",COUNTIFS(ParticipantsDB!F2:F200,IFERROR(INDEX(SessionDB!$R$2:$R$50,2),""),ParticipantsDB!G2:G200,"Non-Local"))
A22: =IFERROR(INDEX(SessionDB!$R$2:$R$50,3),"") | B22: =IF(A22="","",COUNTIF(ParticipantsDB!F2:F200,A22)) | D22: =IF(IFERROR(INDEX(SessionDB!$R$2:$R$50,3),"")="","",IFERROR(INDEX(SessionDB!$R$2:$R$50,3),"")&" — Local") | E22: =IF(D22="","",COUNTIFS(ParticipantsDB!F2:F200,IFERROR(INDEX(SessionDB!$R$2:$R$50,3),""),ParticipantsDB!G2:G200,"Local"))
A23: =IFERROR(INDEX(SessionDB!$R$2:$R$50,4),"") | B23: =IF(A23="","",COUNTIF(ParticipantsDB!F2:F200,A23)) | D23: =IF(IFERROR(INDEX(SessionDB!$R$2:$R$50,3),"")="","",IFERROR(INDEX(SessionDB!$R$2:$R$50,3),"")&" — Non-Local") | E23: =IF(D23="","",COUNTIFS(ParticipantsDB!F2:F200,IFERROR(INDEX(SessionDB!$R$2:$R$50,3),""),ParticipantsDB!G2:G200,"Non-Local"))
A24: =IFERROR(INDEX(SessionDB!$R$2:$R$50,5),"") | B24: =IF(A24="","",COUNTIF(ParticipantsDB!F2:F200,A24)) | D24: =IF(IFERROR(INDEX(SessionDB!$R$2:$R$50,4),"")="","",IFERROR(INDEX(SessionDB!$R$2:$R$50,4),"")&" — Local") | E24: =IF(D24="","",COUNTIFS(ParticipantsDB!F2:F200,IFERROR(INDEX(SessionDB!$R$2:$R$50,4),""),ParticipantsDB!G2:G200,"Local"))
A25: =IFERROR(INDEX(SessionDB!$R$2:$R$50,6),"") | B25: =IF(A25="","",COUNTIF(ParticipantsDB!F2:F200,A25)) | D25: =IF(IFERROR(INDEX(SessionDB!$R$2:$R$50,4),"")="","",IFERROR(INDEX(SessionDB!$R$2:$R$50,4),"")&" — Non-Local") | E25: =IF(D25="","",COUNTIFS(ParticipantsDB!F2:F200,IFERROR(INDEX(SessionDB!$R$2:$R$50,4),""),ParticipantsDB!G2:G200,"Non-Local"))
A26: =IFERROR(INDEX(SessionDB!$R$2:$R$50,7),"") | B26: =IF(A26="","",COUNTIF(ParticipantsDB!F2:F200,A26)) | D26: =IF(IFERROR(INDEX(SessionDB!$R$2:$R$50,5),"")="","",IFERROR(INDEX(SessionDB!$R$2:$R$50,5),"")&" — Local") | E26: =IF(D26="","",COUNTIFS(ParticipantsDB!F2:F200,IFERROR(INDEX(SessionDB!$R$2:$R$50,5),""),ParticipantsDB!G2:G200,"Local"))
A27: =IFERROR(INDEX(SessionDB!$R$2:$R$50,8),"") | B27: =IF(A27="","",COUNTIF(ParticipantsDB!F2:F200,A27)) | D27: =IF(IFERROR(INDEX(SessionDB!$R$2:$R$50,5),"")="","",IFERROR(INDEX(SessionDB!$R$2:$R$50,5),"")&" — Non-Local") | E27: =IF(D27="","",COUNTIFS(ParticipantsDB!F2:F200,IFERROR(INDEX(SessionDB!$R$2:$R$50,5),""),ParticipantsDB!G2:G200,"Non-Local"))
A28: =IFERROR(INDEX(SessionDB!$R$2:$R$50,9),"") | B28: =IF(A28="","",COUNTIF(ParticipantsDB!F2:F200,A28)) | D28: =IF(IFERROR(INDEX(SessionDB!$R$2:$R$50,6),"")="","",IFERROR(INDEX(SessionDB!$R$2:$R$50,6),"")&" — Local") | E28: =IF(D28="","",COUNTIFS(ParticipantsDB!F2:F200,IFERROR(INDEX(SessionDB!$R$2:$R$50,6),""),ParticipantsDB!G2:G200,"Local"))
A29: =IFERROR(INDEX(SessionDB!$R$2:$R$50,10),"") | B29: =IF(A29="","",COUNTIF(ParticipantsDB!F2:F200,A29)) | D29: =IF(IFERROR(INDEX(SessionDB!$R$2:$R$50,6),"")="","",IFERROR(INDEX(SessionDB!$R$2:$R$50,6),"")&" — Non-Local") | E29: =IF(D29="","",COUNTIFS(ParticipantsDB!F2:F200,IFERROR(INDEX(SessionDB!$R$2:$R$50,6),""),ParticipantsDB!G2:G200,"Non-Local"))
A30: Total (verify) | B30: =COUNTA(ParticipantsDB!A2:A200) | D30: =IF(IFERROR(INDEX(SessionDB!$R$2:$R$50,7),"")="","",IFERROR(INDEX(SessionDB!$R$2:$R$50,7),"")&" — Local") | E30: =IF(D30="","",COUNTIFS(ParticipantsDB!F2:F200,IFERROR(INDEX(SessionDB!$R$2:$R$50,7),""),ParticipantsDB!G2:G200,"Local"))
D31: =IF(IFERROR(INDEX(SessionDB!$R$2:$R$50,7),"")="","",IFERROR(INDEX(SessionDB!$R$2:$R$50,7),"")&" — Non-Local") | E31: =IF(D31="","",COUNTIFS(ParticipantsDB!F2:F200,IFERROR(INDEX(SessionDB!$R$2:$R$50,7),""),ParticipantsDB!G2:G200,"Non-Local"))
D32: =IF(IFERROR(INDEX(SessionDB!$R$2:$R$50,8),"")="","",IFERROR(INDEX(SessionDB!$R$2:$R$50,8),"")&" — Local") | E32: =IF(D32="","",COUNTIFS(ParticipantsDB!F2:F200,IFERROR(INDEX(SessionDB!$R$2:$R$50,8),""),ParticipantsDB!G2:G200,"Local"))
D33: =IF(IFERROR(INDEX(SessionDB!$R$2:$R$50,8),"")="","",IFERROR(INDEX(SessionDB!$R$2:$R$50,8),"")&" — Non-Local") | E33: =IF(D33="","",COUNTIFS(ParticipantsDB!F2:F200,IFERROR(INDEX(SessionDB!$R$2:$R$50,8),""),ParticipantsDB!G2:G200,"Non-Local"))
D34: =IF(IFERROR(INDEX(SessionDB!$R$2:$R$50,9),"")="","",IFERROR(INDEX(SessionDB!$R$2:$R$50,9),"")&" — Local") | E34: =IF(D34="","",COUNTIFS(ParticipantsDB!F2:F200,IFERROR(INDEX(SessionDB!$R$2:$R$50,9),""),ParticipantsDB!G2:G200,"Local"))
D35: =IF(IFERROR(INDEX(SessionDB!$R$2:$R$50,9),"")="","",IFERROR(INDEX(SessionDB!$R$2:$R$50,9),"")&" — Non-Local") | E35: =IF(D35="","",COUNTIFS(ParticipantsDB!F2:F200,IFERROR(INDEX(SessionDB!$R$2:$R$50,9),""),ParticipantsDB!G2:G200,"Non-Local"))
D36: =IF(IFERROR(INDEX(SessionDB!$R$2:$R$50,10),"")="","",IFERROR(INDEX(SessionDB!$R$2:$R$50,10),"")&" — Local") | E36: =IF(D36="","",COUNTIFS(ParticipantsDB!F2:F200,IFERROR(INDEX(SessionDB!$R$2:$R$50,10),""),ParticipantsDB!G2:G200,"Local"))
D37: =IF(IFERROR(INDEX(SessionDB!$R$2:$R$50,10),"")="","",IFERROR(INDEX(SessionDB!$R$2:$R$50,10),"")&" — Non-Local") | E37: =IF(D37="","",COUNTIFS(ParticipantsDB!F2:F200,IFERROR(INDEX(SessionDB!$R$2:$R$50,10),""),ParticipantsDB!G2:G200,"Non-Local"))
D39: DEPARTMENT BREAKDOWN
D40: =IFERROR(INDEX($H$2:$H$50,1),"") | E40: =IF(D40="","",COUNTIF(ParticipantsDB!D2:D200,D40))
D41: =IFERROR(INDEX($H$2:$H$50,2),"") | E41: =IF(D41="","",COUNTIF(ParticipantsDB!D2:D200,D41))
...

Sheet RoomDB
A1: ROOM DATABASE — Source of Truth for Room Reservations
A2: Mark 'R' = Reserved for this event. Leave blank = Not reserved. The macro reads this sheet but NEVER writes to it. Your markings are always safe. | Z2: Main Hall
A3: Room | B3: Capacity | C3: Day | D3: 08:00 | E3: 08:30 | F3: 09:00 | G3: 09:30 | H3: 10:00 | I3: 10:30 | J3: 11:00 | K3: 11:30 | L3: 12:00 | M3: 12:30 | N3: 13:00 | O3: 13:30 | P3: 14:00 | Q3: 14:30 | R3: 15:00 | S3: 15:30 | T3: 16:00 | U3: 16:30 | V3: 17:00 | W3: 17:30 | Z3: Room A1
A4: Main Hall | B4: 200 | C4: D1 | D4: R | E4: R | F4: R | G4: R | H4: R | I4: R | J4: R | K4: R | L4: R | M4: R | N4: R | O4: R | P4: R | Q4: R | R4: R | S4: R | T4: R | U4: R | V4: R | W4: R | Z4: Room B1
C5: D2 | D5: R | E5: R | F5: R | G5: R | H5: R | I5: R | J5: R | K5: R | L5: R | M5: R | N5: R | O5: R | P5: R | Q5: R | R5: R | S5: R | T5: R | U5: R | V5: R | W5: R | Z5: Room C1
C6: D3 | D6: R | E6: R | F6: R | G6: R | H6: R | I6: R | J6: R | K6: R | L6: R | M6: R | N6: R | O6: R | P6: R | Q6: R | R6: R | S6: R | T6: R | U6: R | V6: R | W6: R | Z6: Room D1
C7: D4 | D7: R | E7: R | F7: R | G7: R | H7: R | I7: R | J7: R | K7: R | L7: R | M7: R | N7: R | O7: R | P7: R | Q7: R | R7: R | S7: R | T7: R | U7: R | V7: R | W7: R | Z7: Atrium
C8: D5 | D8: R | E8: R | F8: R | G8: R | H8: R | I8: R | J8: R | K8: R | L8: R | M8: R | N8: R | O8: R | P8: R | Q8: R | R8: R | S8: R | T8: R | U8: R | V8: R | W8: R | Z8: Room E1
A9: Room A1 | B9: 50 | C9: D1 | D9: R | E9: R | F9: R | G9: R | H9: R | I9: R | J9: R | K9: R | L9: R | M9: R | N9: R | O9: R | P9: R | Q9: R | R9: R | S9: R | T9: R | U9: R | V9: R | W9: R | Z9: Room E2
C10: D2 | D10: R | E10: R | F10: R | G10: R | H10: R | I10: R | J10: R | K10: R | L10: R | M10: R | N10: R | O10: R | P10: R | Q10: R | R10: R | S10: R | T10: R | U10: R | V10: R | W10: R | Z10: Room F1
C11: D3 | D11: R | E11: R | F11: R | G11: R | H11: R | I11: R | J11: R | K11: R | L11: R | M11: R | N11: R | O11: R | P11: R | Q11: R | R11: R | S11: R | T11: R | U11: R | V11: R | W11: R | Z11: Boardroom G
C12: D4 | D12: R | E12: R | F12: R | G12: R | H12: R | I12: R | J12: R | K12: R | L12: R | M12: R | N12: R | O12: R | P12: R | Q12: R | R12: R | S12: R | T12: R | U12: R | V12: R | W12: R | Z12: Terrace
C13: D5 | D13: R | E13: R | F13: R | G13: R | H13: R | I13: R | J13: R | K13: R | L13: R | M13: R | N13: R | O13: R | P13: R | Q13: R | R13: R | S13: R | T13: R | U13: R | V13: R | W13: R
A14: Room B1 | B14: 55 | C14: D1 | D14: R | E14: R | F14: R | G14: R | H14: R | I14: R | J14: R | K14: R | L14: R | M14: R | N14: R | O14: R | P14: R | Q14: R | R14: R | S14: R | T14: R | U14: R | V14: R | W14: R
C15: D2 | D15: R | E15: R | F15: R | G15: R | H15: R | I15: R | J15: R | K15: R | L15: R | M15: R | N15: R | O15: R | P15: R | Q15: R | R15: R | S15: R | T15: R | U15: R | V15: R | W15: R
C16: D3 | D16: R | E16: R | F16: R | G16: R | H16: R | I16: R | J16: R | K16: R | L16: R | M16: R | N16: R | O16: R | P16: R | Q16: R | R16: R | S16: R | T16: R | U16: R | V16: R | W16: R
C17: D4 | D17: R | E17: R | F17: R | G17: R | H17: R | I17: R | J17: R | K17: R | L17: R | M17: R | N17: R | O17: R | P17: R | Q17: R | R17: R | S17: R | T17: R | U17: R | V17: R | W17: R
C18: D5 | D18: R | E18: R | F18: R | G18: R | H18: R | I18: R | J18: R | K18: R | L18: R | M18: R | N18: R | O18: R | P18: R | Q18: R | R18: R | S18: R | T18: R | U18: R | V18: R | W18: R
A19: Room C1 | B19: 45 | C19: D1 | D19: R | E19: R | F19: R | G19: R | H19: R | I19: R | J19: R | K19: R | L19: R | M19: R | N19: R | O19: R | P19: R | Q19: R | R19: R | S19: R | T19: R | U19: R | V19: R | W19: R
C20: D2 | D20: R | E20: R | F20: R | G20: R | H20: R | I20: R | J20: R | K20: R | L20: R | M20: R | N20: R | O20: R | P20: R | Q20: R | R20: R | S20: R | T20: R | U20: R | V20: R | W20: R
C21: D3 | D21: R | E21: R | F21: R | G21: R | H21: R | I21: R | J21: R | K21: R | L21: R | M21: R | N21: R | O21: R | P21: R | Q21: R | R21: R | S21: R | T21: R | U21: R | V21: R | W21: R
C22: D4 | D22: R | E22: R | F22: R | G22: R | H22: R | I22: R | J22: R | K22: R | L22: R | M22: R | N22: R | O22: R | P22: R | Q22: R | R22: R | S22: R | T22: R | U22: R | V22: R | W22: R
C23: D5 | D23: R | E23: R | F23: R | G23: R | H23: R | I23: R | J23: R | K23: R | L23: R | M23: R | N23: R | O23: R | P23: R | Q23: R | R23: R | S23: R | T23: R | U23: R | V23: R | W23: R
A24: Room D1 | B24: 40 | C24: D1 | D24: R | E24: R | F24: R | G24: R | H24: R | I24: R | J24: R | K24: R | L24: R | M24: R | N24: R | O24: R | P24: R | Q24: R | R24: R | S24: R | T24: R | U24: R | V24: R | W24: R
C25: D2 | D25: R | E25: R | F25: R | G25: R | H25: R | I25: R | J25: R | K25: R | L25: R | M25: R | N25: R | O25: R | P25: R | Q25: R | R25: R | S25: R | T25: R | U25: R | V25: R | W25: R
C26: D3 | D26: R | E26: R | F26: R | G26: R | H26: R | I26: R | J26: R | K26: R | L26: R | M26: R | N26: R | O26: R | P26: R | Q26: R | R26: R | S26: R | T26: R | U26: R | V26: R | W26: R
C27: D4 | D27: R | E27: R | F27: R | G27: R | H27: R | I27: R | J27: R | K27: R | L27: R | M27: R | N27: R | O27: R | P27: R | Q27: R | R27: R | S27: R | T27: R | U27: R | V27: R | W27: R
C28: D5 | D28: R | E28: R | F28: R | G28: R | H28: R | I28: R | J28: R | K28: R | L28: R | M28: R | N28: R | O28: R | P28: R | Q28: R | R28: R | S28: R | T28: R | U28: R | V28: R | W28: R
A29: Atrium | B29: 250 | C29: D1 | D29: R | E29: R | F29: R | G29: R | H29: R | I29: R | J29: R | K29: R | L29: R | M29: R | N29: R | O29: R | P29: R | Q29: R | R29: R | S29: R | T29: R | U29: R | V29: R | W29: R
C30: D2 | D30: R | E30: R | F30: R | G30: R | H30: R | I30: R | J30: R | K30: R | L30: R | M30: R | N30: R | O30: R | P30: R | Q30: R | R30: R | S30: R | T30: R | U30: R | V30: R | W30: R
C31: D3 | D31: R | E31: R | F31: R | G31: R | H31: R | I31: R | J31: R | K31: R | L31: R | M31: R | N31: R | O31: R | P31: R | Q31: R | R31: R | S31: R | T31: R | U31: R | V31: R | W31: R
C32: D4 | D32: R | E32: R | F32: R | G32: R | H32: R | I32: R | J32: R | K32: R | L32: R | M32: R | N32: R | O32: R | P32: R | Q32: R | R32: R | S32: R | T32: R | U32: R | V32: R | W32: R
C33: D5 | D33: R | E33: R | F33: R | G33: R | H33: R | I33: R | J33: R | K33: R | L33: R | M33: R | N33: R | O33: R | P33: R | Q33: R | R33: R | S33: R | T33: R | U33: R | V33: R | W33: R
A34: Room E1 | B34: 35 | C34: D1
C35: D2
C36: D3
C37: D4
C38: D5
A39: Room E2 | B39: 30 | C39: D1
C40: D2
...

Sheet Room Management
A1: ROOM MANAGEMENT — Auto-Generated (Do Not Edit — Run Macro to Refresh)
A2: Day | B2: Time | C2: Main Hall (200 pax) | D2: Room A1 (50 pax) | E2: Room B1 (55 pax) | F2: Room C1 (45 pax) | G2: Room D1 (40 pax) | H2: Atrium (250 pax) | I2: Room E1 (35 pax) | J2: Room E2 (30 pax) | K2: Room F1 (25 pax) | L2: Boardroom G (15 pax) | M2: Terrace (60 pax)
A3: D1 | B3: 08:00
A4: D1 | B4: 08:30
A5: D1 | B5: 09:00
A6: D1 | B6: 09:30
A7: D1 | B7: 10:00
A8: D1 | B8: 10:30
A9: D1 | B9: 11:00
A10: D1 | B10: 11:30
A11: D1 | B11: 12:00
A12: D1 | B12: 12:30
A13: D1 | B13: 13:00
A14: D1 | B14: 13:30
... A102: D5 | B102: 17:30
A104: LEGEND: ■ Green/R = Reserved (available) | ■ Blue = Booked | ■ Gray = Not reserved | ■ Red = CONFLICT or OVERLAP
A105: This sheet is auto-generated. Edit RoomDB to change reservations, edit SessionDB to change bookings, then run RefreshRoomManagement macro.

Sheet Agenda
A1: WORKSHOP PROGRAM 2026 (AGENDA | TIMETABLE)
A2: 23 Mar (Mon) | K2: 24 Mar (Tue) | U2: 25 Mar (Wed) | AE2: 26 Mar (Thu) | AO2: 27 Mar (Fri)
A3: Time | B3: Agenda | C3: Lead | D3: Agenda | E3: Lead | F3: Agenda | G3: Lead | H3: Agenda | I3: Lead | K3: Time | L3: Agenda | M3: Lead | N3: Agenda | O3: Lead | P3: Agenda | Q3: Lead | R3: Agenda | S3: Lead | U3: Time | V3: Agenda | W3: Lead | X3: Agenda | Y3: Lead | Z3: Agenda | AA3: Lead | AB3: Agenda | AC3: Lead | AE3: Time | AF3: Agenda | AG3: Lead | AH3: Agenda | AI3: Lead | AJ3: Agenda | AK3: Lead | AL3: Agenda | AM3: Lead | AO3: Time | AP3: Agenda | AQ3: Lead | AR3: Agenda | AS3: Lead | AT3: Agenda | AU3: Lead | AV3: Agenda | AW3: Lead
A4: 08:00 | K4: 08:00 | U4: 08:00 | AE4: 08:00 | AO4: 08:00
A5: 08:30 | K5: 08:30 | U5: 08:30 | AE5: 08:30 | AO5: 08:30
A6: 09:00 | B6: Opening Keynote | K6: 09:00 | L6: Emotional Intelligence | M6: Aisha Johnson | N6: Security Fundamentals | O6: Alex Novak | P6: Design Systems | Q6: Yuki Tanaka | R6: Capacity Planning | S6: James Wright | U6: 09:00 | V6: Midweek Keynote | AE6: 09:00 | AF6: Coaching Skills | AG6: Mark Torres | AH6: System Architecture | AI6: David Kim | AJ6: Data Visualization | AK6: Carlos Ruiz | AL6: Change Management | AM6: James Wright | AO6: 09:00 | AP6: Personal Action Plans | AQ6: Mark Torres | AR6: Tech Roadmapping | AS6: David Kim | AT6: Portfolio Building | AU6: Carlos Ruiz | AV6: Continuous Improvement | AW6: James Wright
A7: 09:30 | K7: 09:30 | U7: 09:30 | AE7: 09:30 | AO7: 09:30
A8: 10:00 | K8: 10:00 | U8: 10:00 | V8: Morning Break | AE8: 10:00 | AO8: 10:00
A9: 10:30 | B9: Leading Through Change | C9: Mark Torres | D9: API Design Patterns | E9: Priya Sharma | F9: Empathy Mapping 101 | G9: Lena Müller | H9: Lean Process Improvement | I9: James Wright | K9: 10:30 | L9: Morning Break | U9: 10:30 | V9: Cross-Team Collaboration | W9: Aisha Johnson | X9: AI/ML Integration | Y9: Wei Zhang | Z9: Workshop Facilitation | AA9: Lena Müller | AB9: Incident Response | AC9: Alex Novak | AE9: 10:30 | AF9: Morning Break | AO9: 10:30 | AP9: Morning Break
A10: 11:00 | K10: 11:00 | L10: Panel: Future of Work | U10: 11:00 | AE10: 11:00 | AF10: Presentation Mastery | AG10: Tom Bradley | AH10: Testing Strategies | AI10: Priya Sharma | AJ10: Design Critiques | AK10: Yuki Tanaka | AL10: Process Automation | AM10: Nina Petrov | AO10: 11:00 | AP10: Track Showcases
A11: 11:30 | K11: 11:30 | U11: 11:30 | AE11: 11:30 | AO11: 11:30
A12: 12:00 | B12: Lunch & Networking | K12: 12:00 | L12: Lunch & Networking | U12: 12:00 | V12: Lunch & Networking | AE12: 12:00 | AO12: 12:00 | AP12: Farewell Lunch
A13: 12:30 | K13: 12:30 | U13: 12:30 | AE13: 12:30 | AF13: Lunch & Networking | AO13: 12:30
A14: 13:00 | B14: Stakeholder Alignment | C14: Aisha Johnson | D14: Cloud Infrastructure | E14: David Kim | F14: Prototyping Sprint | G14: Carlos Ruiz | H14: Risk Assessment | I14: Nina Petrov | K14: 13:00 | L14: Conflict Resolution | M14: Mark Torres | N14: DevOps Practices | O14: Priya Sharma | P14: Accessibility Workshop | Q14: Carlos Ruiz | R14: Vendor Management | S14: Nina Petrov | U14: 13:00 | V14: Cross-Track Hackathon | AE14: 13:00 | AO14: 13:00 | AP14: Closing Keynote & Awards
A15: 13:30 | K15: 13:30 | U15: 13:30 | AE15: 13:30 | AF15: Succession Planning | AG15: Aisha Johnson | AH15: Code Review Culture | AI15: Alex Novak | AJ15: Design Handoff | AK15: Lena Müller | AL15: KPI Dashboards | AM15: Rachel Green | AO15: 13:30
A16: 14:00 | K16: 14:00 | U16: 14:00 | AE16: 14:00 | AO16: 14:00
A17: 14:30 | B17: Afternoon Break | K17: 14:30 | L17: Afternoon Break | U17: 14:30 | AE17: 14:30 | AO17: 14:30
A18: 15:00 | B18: Feedback Culture | C18: Tom Bradley | D18: Data Pipeline Design | E18: Wei Zhang | F18: Service Blueprinting | G18: Lena Müller | H18: Agile Ceremonies | I18: Rachel Green | K18: 15:00 | L18: Strategic Planning | M18: Tom Bradley | N18: Performance Testing | O18: David Kim | P18: User Research Methods | Q18: Yuki Tanaka | R18: Budget Forecasting | S18: Rachel Green | U18: 15:00 | AE18: 15:00 | AF18: Afternoon Break | AO18: 15:00
A19: 15:30 | K19: 15:30 | U19: 15:30 | AE19: 15:30 | AF19: Hackathon Presentations | AO19: 15:30
A20: 16:00 | K20: 16:00 | U20: 16:00 | AE20: 16:00 | AO20: 16:00
A21: 16:30 | K21: 16:30 | U21: 16:30 | AE21: 16:30 | AO21: 16:30
A22: 17:00 | K22: 17:00 | U22: 17:00 | AE22: 17:00 | AO22: 17:00
A23: 17:30 | K23: 17:30 | U23: 17:30 | AE23: 17:30 | AO23: 17:30

Sheet Speakers
A1: Speaker | B1: Track(s) | C1: Sessions | D1: Room(s) | E1: Days
A2: Aisha Johnson | B2: Leadership | C2: Stakeholder Alignment; Emotional Intelligence; Cross-Team Collaboration | D2: Leadership | E2: 1, 2, 3, 4
A3: Alex Novak | B3: Operations, Technical | C3: Security Fundamentals; Incident Response; Code Review Culture | D3: Operations, Technical | E3: 2, 3, 4
A4: Carlos Ruiz | B4: Design Thinking | C4: Prototyping Sprint; Accessibility Workshop; Data Visualization | D4: Design Thinking | E4: 1, 2, 4, 5
A5: David Kim | B5: Technical | C5: Cloud Infrastructure; Performance Testing; System Architecture | D5: Technical | E5: 1, 2, 4, 5
A6: Dr. Sarah Chen | B6: Keynote | C6: Opening Keynote; Midweek Keynote; Closing Keynote & Awards | D6: Keynote | E6: 1, 3, 5
A7: James Wright | B7: Operations | C7: Lean Process Improvement; Capacity Planning; Change Management | D7: Operations | E7: 1, 2, 4, 5
A8: Lena Müller | B8: Design Thinking | C8: Empathy Mapping 101; Service Blueprinting; Workshop Facilitation | D8: Design Thinking | E8: 1, 3, 4
A9: Mark Torres | B9: Leadership | C9: Leading Through Change; Conflict Resolution; Coaching Skills | D9: Leadership | E9: 1, 2, 4, 5
A10: Nina Petrov | B10: Operations | C10: Risk Assessment; Vendor Management; Process Automation | D10: Operations | E10: 1, 2, 4
A11: Priya Sharma | B11: Technical | C11: API Design Patterns; DevOps Practices; Testing Strategies | D11: Technical | E11: 1, 2, 4
A12: Rachel Green | B12: Operations | C12: Agile Ceremonies; Budget Forecasting; KPI Dashboards | D12: Operations | E12: 1, 2, 4
... A15: Yuki Tanaka | B15: Design Thinking | C15: Design Systems; User Research Methods; Design Critiques | D15: Design Thinking | E15: 2, 4

Sheet How To Use
A1: WORKSHOP TIMETABLE v4 — AUTO-UPDATING GUIDE
A3: HOW IT WORKS
A4: The Day 1–5 sheets pull session data live from the SessionDB sheet using INDEX/MATCH array formulas.
A5: When you edit SessionDB (title, speaker, room, time, track), the Day sheets update instantly.
A7: EXCEL VERSION COMPATIBILITY
A8: Excel 365 / Excel 2021: Formulas work automatically. No extra steps needed.
A9: Excel 2019 / 2016: You must activate array formulas manually. Select all formula cells (B4:E23 on any Day sheet), press F2, then press Ctrl+Shift+Enter. You will see curly braces {} around the formula in the formula bar. You only need to do this once per sheet.
A10: Excel Online / SharePoint: Array formulas with MATCH(1,...,0) may not calculate. Use the VBA macro approach instead (see below).
A12: HOW TO EDIT SESSIONS
A13: 1. Go to SessionDB sheet.
A14: 2. Edit any value: title, speaker, room, start time, end time, track.
A15: 3. Switch to the Day sheet — the change is already there.
... A44: 4. If nothing works: use the VBA macro approach — it bypasses all formula issues.
